Workbook

Sheet README
B1: FP&A Demo Project for Upwork
A2: Sample SaaS model template: 24-month forecast, 3 financial statements, dashboard, and quality checks.
B4: 1) Quick Start Guide
B5: Select Scenario | C5: Data_Entry!B5: Base / Upside / Downside | D5: Use this to switch growth, churn, and margin assumptions | E5: Start from the Data_Entry sheet
B6: Update Input Data | C6: Yellow cells on Data_Entry | D6: These are editable input cells | E6: Data_Entry only
B7: Review Output | C7: IS / CF / BS / Dashboard / Checks | D7: Review the impact on EBITDA, cash, and headcount | E7: Share screenshots with the client
B10: 2) FP&A Workflow from A to Z
B11: Step | C11: What to do | D11: Deliverable
B12: A. Scope & Objectives | C12: Define the required model scope: budget, forecast, 3-statement model, cash runway, dashboard, and scenario planning. | D12: Project brief / SOW
B13: B. Data request | C13: Request the trial balance / historical P&L, payroll, sales pipeline, contracts, capex, debt, and working capital data. | D13: Data request list
B14: C. Standardize Actuals | C14: Clean the chart of accounts, map revenue / COGS / Opex, and resolve missing data. | D14: Clean actuals
B15: D. Define Drivers | C15: Select key business drivers: customers, ARPU, churn, headcount, marketing %, DSO, DPO, and capex. | D15: Assumption tree
B16: E. Build schedules | C16: Revenue, headcount, opex, capex, working capital, debt schedule. | D16: Supporting schedules
B17: F. 3 financial statements | C17: Link the Income Statement, Cash Flow Statement, and Balance Sheet. | D17: Integrated model
B18: G. Scenarios | C18: Build Base / Upside / Downside cases and sensitivities. | D18: Scenario model
B19: H. Dashboard & KPIs | C19: Revenue growth, gross margin, EBITDA, cash runway, ending customers, ending headcount. | D19: Client dashboard
B20: I. QA & handoff | C20: Prepare QA checks, documentation, user instructions, and optionally a video walkthrough or PDF snapshot. | D20: Final deliverables
B23: 3) Suggested Deliverables for Upwork
B24: Item | C24: Description
B25: Model file | C25: Workbook with Control / Assumptions / Schedules / 3 statements / Dashboard / Checks
B26: Executive summary | C26: One-page summary of insights: growth, margin, burn, cash needs, and hiring plan
B27: Scenario analysis | C27: Base vs Upside vs Downside, with sensitivity analysis for revenue and cash
B28: Client handoff | C28: README + color legend for inputs/formulas/links + monthly update instructions
B29: Client request list | C29: Tracker for dependencies, open items, due dates, and delivery status during the engagement
B30: Assumption log | C30: Audit-style register of key model drivers linked to Data_Entry for client review and sign-off
B31: Executive summary | C31: One-page summary linked to selected scenario and annual KPI outputs for handoff or proposal screenshots

Sheet Source_Notes
A1: HubSpot (HUBS) — FP&A Model Assumptions & Sources
A2: All figures in USD. Data sourced from public SEC filings.
A4: Input | B4: Value Used | C4: Source / Notes
A5: Model Start Date | B5: Jan 1, 2024 | C5: HubSpot FY2024 model — 24-month forecast from Jan 2024
A6: Initial Cash | B6: $1,388M | C6: Cash $388M + ST Investments $1,000M — HubSpot 10-K Dec 31 2023
A7: Initial AR | B7: $295M | C7: Accounts receivable net — HubSpot 10-K Dec 31 2023
A8: Initial Net PP&E | B8: $240M | C8: Estimated from total assets composition — HubSpot 10-K 2023
A9: Initial AP | B9: $9.1M | C9: Accounts payable — HubSpot 10-K Dec 31 2023 (very low, asset-light SaaS)
A10: Initial Debt | B10: $456M | C10: Convertible senior notes — HubSpot 10-K Dec 31 2023
A11: Share Capital (APIC) | B11: $2,137M | C11: Additional paid-in capital — HubSpot 10-K Dec 31 2023
A12: Opening Retained Earnings | B12: -$818.7M | C12: Accumulated deficit — HubSpot 10-K Dec 31 2023
A13: Beginning Customers | B13: 205,091 | C13: HubSpot Q4 2023 Earnings Release (8-K Feb 2024)
A14: Monthly New Customers (Base) | B14: 3,800 | C14: Net adds 2024: 42,848 ÷ 12 = 3,571. Gross adds est. +6% for churn offset
A15: Monthly Churn % (Base) | B15: 1.5% | C15: Estimated from NRR 104% (Q4 2024). Gross churn ~1.5%/mo for SMB mix
... A34: Marketing Salary | B34: $90,000/yr | C34: Marketing generalist to manager average
A36: Key Disclosure
A37: This model uses illustrative assumptions based on publicly available data.
A38: Actual internal figures will differ. Suitable for portfolio / educational use only.
A39: Sources: HubSpot SEC 8-K filings, 10-K 2023 & 2024, ir.hubspot.com

Sheet Data_Entry
A1: Data Entry Hub
A2: Update yellow cells only. All schedules, the 3 statements, dashboard, and checks update automatically.
A4: 1. Model Controls
A5: Selected Scenario | B5: Base | C5: Choose Base / Upside / Downside here
A9: 2. Scenario Assumptions
A10: Metric | B10: Base | C10: Upside | D10: Downside | E10: Selected | F10: Unit | G10: Notes
A11: Model Start Date | B11: 45292 | C11: 45292 | D11: 45292 | E11: =IF($B$5="Upside",C11,IF($B$5="Downside",D11,B11)) | F11: date | G11: Timeline start for monthly forecast
A12: Initial Cash | B12: 1388000000 | C12: 1388000000 | D12: 1388000000 | E12: =IF($B$5="Upside",C12,IF($B$5="Downside",D12,B12)) | F12: USD | G12: Opening cash on balance sheet
A13: Initial AR | B13: 295303000 | C13: 295303000 | D13: 295303000 | E13: =IF($B$5="Upside",C13,IF($B$5="Downside",D13,B13)) | F13: USD | G13: Opening accounts receivable
A14: Initial Net PP&E | B14: 240000000 | C14: 240000000 | D14: 240000000 | E14: =IF($B$5="Upside",C14,IF($B$5="Downside",D14,B14)) | F14: USD | G14: Opening net fixed assets
A15: Initial AP | B15: 9106000 | C15: 9106000 | D15: 9106000 | E15: =IF($B$5="Upside",C15,IF($B$5="Downside",D15,B15)) | F15: USD | G15: Opening accounts payable
A16: Initial Debt | B16: 456206000 | C16: 456206000 | D16: 456206000 | E16: =IF($B$5="Upside",C16,IF($B$5="Downside",D16,B16)) | F16: USD | G16: Opening interest-bearing debt
A17: Share Capital | B17: 2136908000 | C17: 2136908000 | D17: 2136908000 | E17: =IF($B$5="Upside",C17,IF($B$5="Downside",D17,B17)) | F17: USD | G17: Static equity capital
A18: Opening Retained Earnings | B18: -818676000 | C18: -818676000 | D18: -818676000 | E18: =IF($B$5="Upside",C18,IF($B$5="Downside",D18,B18)) | F18: USD | G18: Opening retained earnings
A19: Beginning Customers | B19: 205091 | C19: 205091 | D19: 205091 | E19: =IF($B$5="Upside",C19,IF($B$5="Downside",D19,B19)) | F19: customers | G19: Opening subscriber count
A20: Monthly New Customers | B20: 3800 | C20: 4200 | D20: 3200 | E20: =IF($B$5="Upside",C20,IF($B$5="Downside",D20,B20)) | F20: customers | G20: Average monthly gross adds
A21: Monthly Churn % | B21: 0.015 | C21: 0.012 | D21: 0.02 | E21: =IF($B$5="Upside",C21,IF($B$5="Downside",D21,B21)) | F21: % | G21: Monthly customer churn rate
A22: Starting ARPU | B22: 947 | C22: 960 | D22: 920 | E22: =IF($B$5="Upside",C22,IF($B$5="Downside",D22,B22)) | F22: USD | G22: Average revenue per customer per month
... A47: Other G&A / month | B47: 3000000 | C47: 3000000 | D47: 3000000 | E47: =IF($B$5="Upside",C47,IF($B$5="Downside",D47,B47)) | F47: USD | G47: Insurance, audit, admin and misc.
A49: 3. Monthly New Customer Schedule (override base assumption per month)
A50: Leave cells blank to use base scenario assumption. Enter a number to override that specific month.
A51: Monthly New Customers Override | B51: =Data_Entry!$E$11 | C51: =DATE(YEAR(B51),MONTH(B51)+1,1) | D51: =DATE(YEAR(C51),MONTH(C51)+1,1) | E51: =DATE(YEAR(D51),MONTH(D51)+1,1) | F51: =DATE(YEAR(E51),MONTH(E51)+1,1) | G51: =DATE(YEAR(F51),MONTH(F51)+1,1) | H51: =DATE(YEAR(G51),MONTH(G51)+1,1) | I51: =DATE(YEAR(H51),MONTH(H51)+1,1) | J51: =DATE(YEAR(I51),MONTH(I51)+1,1) | ... Y51: =DATE(YEAR(X51),MONTH(X51)+1,1)
A52: New Customers (blank = use base)
A54: 3. Monthly Hiring Plan
A55: Department / Movement | B55: =Data_Entry!$E$11 | C55: =DATE(YEAR(B51),MONTH(B51)+1,1) | D55: =DATE(YEAR(C51),MONTH(C51)+1,1) | E55: =DATE(YEAR(D51),MONTH(D51)+1,1) | F55: =DATE(YEAR(E51),MONTH(E51)+1,1) | G55: =DATE(YEAR(F51),MONTH(F51)+1,1) | H55: =DATE(YEAR(G51),MONTH(G51)+1,1) | I55: =DATE(YEAR(H51),MONTH(H51)+1,1) | J55: =DATE(YEAR(I51),MONTH(I51)+1,1) | ... Y55: =DATE(YEAR(X51),MONTH(X51)+1,1)
A56: Sales Hires | B56: 0 | C56: 0 | D56: 1 | E56: 0 | F56: 0 | G56: 0 | H56: 1 | I56: 0 | J56: 0 | K56: 0 | L56: 1 | M56: 0 | N56: 0 | O56: 0 | P56: 1 | Q56: 0 | R56: 0 | S56: 0 | T56: 1 | U56: 0 | V56: 0 | W56: 0 | X56: 1 | Y56: 0
A57: Sales Terms | B57: 0 | C57: 0 | D57: 0 | E57: 0 | F57: 0 | G57: 0 | H57: 0 | I57: 0 | J57: 0 | K57: 0 | L57: 0 | M57: 0 | N57: 0 | O57: 0 | P57: 0 | Q57: 0 | R57: 0 | S57: 0 | T57: 0 | U57: 0 | V57: 0 | W57: 0 | X57: 0 | Y57: 0
A58: Marketing Hires | B58: 0 | C58: 0 | D58: 0 | E58: 0 | F58: 0 | G58: 0 | H58: 0 | I58: 0 | J58: 0 | K58: 1 | L58: 0 | M58: 0 | N58: 0 | O58: 0 | P58: 0 | Q58: 0 | R58: 0 | S58: 0 | T58: 0 | U58: 0 | V58: 0 | W58: 1 | X58: 0 | Y58: 0
A59: Marketing Terms | B59: 0 | C59: 0 | D59: 0 | E59: 0 | F59: 0 | G59: 0 | H59: 0 | I59: 0 | J59: 0 | K59: 0 | L59: 0 | M59: 0 | N59: 0 | O59: 0 | P59: 0 | Q59: 0 | R59: 0 | S59: 0 | T59: 0 | U59: 0 | V59: 0 | W59: 0 | X59: 0 | Y59: 0
A60: R&D Hires | B60: 0 | C60: 0 | D60: 0 | E60: 0 | F60: 0 | G60: 1 | H60: 0 | I60: 0 | J60: 0 | K60: 0 | L60: 0 | M60: 0 | N60: 0 | O60: 1 | P60: 0 | Q60: 0 | R60: 0 | S60: 0 | T60: 0 | U60: 0 | V60: 0 | W60: 1 | X60: 0 | Y60: 0
A61: R&D Terms | B61: 0 | C61: 0 | D61: 0 | E61: 0 | F61: 0 | G61: 0 | H61: 0 | I61: 0 | J61: 0 | K61: 0 | L61: 0 | M61: 0 | N61: 0 | O61: 0 | P61: 0 | Q61: 0 | R61: 0 | S61: 0 | T61: 0 | U61: 0 | V61: 0 | W61: 0 | X61: 0 | Y61: 0
A62: G&A Hires | B62: 0 | C62: 0 | D62: 0 | E62: 0 | F62: 0 | G62: 0 | H62: 0 | I62: 0 | J62: 0 | K62: 0 | L62: 0 | M62: 0 | N62: 0 | O62: 0 | P62: 0 | Q62: 0 | R62: 0 | S62: 1 | T62: 0 | U62: 0 | V62: 0 | W62: 0 | X62: 0 | Y62: 0
A63: G&A Terms | B63: 0 | C63: 0 | D63: 0 | E63: 0 | F63: 0 | G63: 0 | H63: 0 | I63: 0 | J63: 0 | K63: 0 | L63: 0 | M63: 0 | N63: 0 | O63: 0 | P63: 0 | Q63: 0 | R63: 0 | S63: 0 | T63: 0 | U63: 0 | V63: 0 | W63: 0 | X63: 0 | Y63: 0
A64: Customer Success Hires | B64: 0 | C64: 0 | D64: 0 | E64: 0 | F64: 0 | G64: 0 | H64: 0 | I64: 0 | J64: 1 | K64: 0 | L64: 0 | M64: 0 | N64: 0 | O64: 0 | P64: 0 | Q64: 0 | R64: 0 | S64: 1 | T64: 0 | U64: 0 | V64: 0 | W64: 0 | X64: 0 | Y64: 0
A65: Customer Success Terms | B65: 0 | C65: 0 | D65: 0 | E65: 0 | F65: 0 | G65: 0 | H65: 0 | I65: 0 | J65: 0 | K65: 0 | L65: 0 | M65: 0 | N65: 0 | O65: 0 | P65: 0 | Q65: 0 | R65: 0 | S65: 0 | T65: 0 | U65: 0 | V65: 0 | W65: 0 | X65: 0 | Y65: 0
A68: 4. Monthly Debt Inputs
A69: Debt Input | B69: =Data_Entry!B51 | C69: =Data_Entry!C51 | D69: =Data_Entry!D51 | E69: =Data_Entry!E51 | F69: =Data_Entry!F51 | G69: =Data_Entry!G51 | H69: =Data_Entry!H51 | I69: =Data_Entry!I51 | ... Y69: =Data_Entry!Y51
A70: Debt Draws | B70: 0 | C70: 0 | D70: 0 | E70: 0 | F70: 0 | G70: 0 | H70: 0 | I70: 0 | J70: 0 | K70: 0 | L70: 0 | M70: 0 | N70: 0 | O70: 0 | P70: 0 | Q70: 0 | R70: 0 | S70: 0 | T70: 0 | U70: 0 | V70: 0 | W70: 0 | X70: 0 | Y70: 0
A71: Debt Repayments | H71: 0 | I71: 0 | J71: 0 | K71: 0 | L71: 0 | M71: 5000 | N71: 5000 | O71: 5000 | P71: 5000 | Q71: 5000 | R71: 5000 | S71: 5000 | T71: 5000 | U71: 5000 | V71: 5000 | W71: 5000 | X71: 5000 | Y71: 5000
A74: 5. Input Notes
...

Sheet Input_Source_Map
A1: Input Source Map
A2: All current values in Data_Entry are sample demo assumptions. Replace them with client actuals, budget inputs, or management guidance using the source map below.
A4: How to Use This Sheet
A5: 1) Update yellow cells on Data_Entry only.
A6: 2) Use this sheet to know where each input should come from in a real client project.
A7: 3) Typical sources include accounting / ERP, payroll, CRM, board budget, and treasury schedules.
A9: Section | B9: Data_Entry Ref | C9: Input Item | D9: Meaning | E9: Typical Real-World Source | F9: Typical Owner / System | G9: Update Timing | H9: Demo / Portfolio Note
A10: Model Controls | B10: Data_Entry!B5 | C10: Selected Scenario | D10: Chooses Base / Upside / Downside case used by the full model. | E10: FP&A scenario pack, budget presentation, or management planning deck. | F10: FP&A Manager / CFO | G10: When presenting cases | H10: Current workbook is preloaded to Base for demo purposes.
A11: Opening Balance | B11: Data_Entry!B11:D11 | C11: Model Start Date | D11: First forecast month. | E11: Forecast calendar agreed with management or budget cycle. | F11: FP&A | G11: Once per model build | H11: Usually fixed at kickoff.
A12: Opening Balance | B12: Data_Entry!B12:D12 | C12: Initial Cash | D12: Opening cash balance. | E12: Latest balance sheet, bank statement, or trial balance. | F12: Controller / Treasury / ERP | G12: Monthly close | H12: Replace demo number with month-end actuals.
A13: Opening Balance | B13: Data_Entry!B13:D13 | C13: Initial AR | D13: Opening accounts receivable. | E13: AR aging report or latest balance sheet. | F13: Accounting / ERP | G13: Monthly close | H13: Should tie to AR aging.
A14: Opening Balance | B14: Data_Entry!B14:D14 | C14: Initial Net PP&E | D14: Opening net fixed assets. | E14: Fixed asset register or latest balance sheet. | F14: Accounting / ERP | G14: Monthly close | H14: Tie to fixed asset schedule.
A15: Opening Balance | B15: Data_Entry!B15:D15 | C15: Initial AP | D15: Opening accounts payable. | E15: AP aging report or latest balance sheet. | F15: Accounting / ERP | G15: Monthly close | H15: Should tie to AP aging.
A16: Opening Balance | B16: Data_Entry!B16:D16 | C16: Initial Debt | D16: Opening interest-bearing debt. | E16: Debt schedule, loan statement, or balance sheet. | F16: Treasury / Controller | G16: Monthly close | H16: Tie to lender statements.
A17: Opening Balance | B17: Data_Entry!B17:D17 | C17: Share Capital | D17: Opening contributed equity. | E17: Balance sheet or prior audited financials. | F17: Controller | G17: Rarely changes | H17: Usually static unless equity event occurs.
A18: Opening Balance | B18: Data_Entry!B18:D18 | C18: Opening Retained Earnings | D18: Accumulated earnings brought forward. | E18: Balance sheet or prior period close file. | F18: Controller | G18: Monthly close | H18: Should roll from prior closing retained earnings.
A19: Revenue Drivers | B19: Data_Entry!B19:D19 | C19: Beginning Customers | D19: Opening active customer count. | E19: CRM, billing system, or subscription report. | F19: Revenue Ops / CRM / Billing | G19: Monthly close | H19: Tie to start-of-period customer base.
A20: Revenue Drivers | B20: Data_Entry!B20:D20 | C20: Monthly New Customers | D20: Average monthly gross customer adds. | E20: Sales pipeline, bookings plan, or historical conversion trend. | F20: Sales Ops / FP&A / CRM | G20: Monthly or reforecast | H20: Often linked to sales target.
... A59: Debt Inputs | B59: Data_Entry!B67:Y67 | C59: Debt Repayments | D59: Monthly principal repayments. | E59: Debt amortization schedule, lender notice, or treasury plan. | F59: Treasury / CFO | G59: When financing changes | H59: Enter monthly principal only; interest is calculated.
A62: Tip: In a live client project, tie opening balances to the last closed month, tie headcount to HR/payroll, and tie revenue drivers to CRM or billing reports.

Sheet Executive_Summary
A1: Executive Summary
A2: Client-ready one-page overview linked to the selected scenario and model outputs.
A4: Project Snapshot
A5: Metric | B5: Value | C5: Metric | D5: Value | F5: Metric | G5: Value | H5: Notes
A6: Selected Scenario | B6: =Data_Entry!$B$5 | C6: Forecast Start | D6: =Dashboard!$B$4 | F6: Forecast End | G6: =Dashboard!$Y$4 | H6: Use this page for proposal screenshots or client handoff.
A7: Year 1 | B7: =Dashboard!$C$13 | C7: Year 2 | D7: =Dashboard!$D$13 | F7: Cash Check | G7: =Checks!$D$9 | H7: Checks sheet confirms minimum ending cash and BS balance.
A9: Annual KPI Summary
A10: Metric | B10: Year 1 | C10: Year 2 | D10: Change | F10: Key Readout | G10: Formula | H10: Status
A11: Revenue | B11: =Dashboard!$C$14 | C11: =Dashboard!$D$14 | D11: =IF(B11=0,"-",C11/B11-1) | F11: Revenue growth | G11: =IF(D11="-","n/a",IF(D11>0,"Growing","Declining")) | H11: =IF(D11="-","REVIEW",IF(D11>=0,"OK","REVIEW"))
A12: EBITDA | B12: =Dashboard!$C$15 | C12: =Dashboard!$D$15 | D12: =C12-B12 | F12: Profit improvement | G12: =IF(D12>0,"Improving","Declining") | H12: =IF(C12>=0,"OK","REVIEW")
A13: EBITDA Margin | B13: =Dashboard!$C$16 | C13: =Dashboard!$D$16 | D13: =C13-B13 | F13: Margin trend | G13: =IF(D13>0,"Improving","Compressing") | H13: =IF(C13>=0,"OK","REVIEW")
A14: Ending Cash | B14: =Dashboard!$C$17 | C14: =Dashboard!$D$17 | D14: =C14-B14 | F14: Liquidity | G14: =IF(C14>0,"Positive","Negative") | H14: =IF(C14>0,"OK","REVIEW")
A15: Ending Customers | B15: =Dashboard!$C$18 | C15: =Dashboard!$D$18 | D15: =C15-B15 | F15: Customer base | G15: =IF(D15>0,"Expanded","Contracted") | H15: =IF(C15>=B15,"OK","REVIEW")
A16: Ending HC | B16: =Dashboard!$C$19 | C16: =Dashboard!$D$19 | D16: =C16-B16 | F16: Organization size | G16: =IF(D16>0,"Scaled up","Flat / down") | H16: Informational
A18: Auto Checks & Handoff Notes
A19: =IF(MIN(CF!B19:Y19)>0,"PASS: ending cash remains positive across the full forecast horizon.","REVIEW: ending cash goes negative during the forecast horizon.")
A20: =IF(ABS(BS!Y19)<1,"PASS: the balance sheet remains in balance in the final forecast month.","REVIEW: the balance sheet is out of balance in the final forecast month.")
A21: =IF(Dashboard!D16>=Dashboard!C16,"Year 2 EBITDA margin is at or above Year 1.","Year 2 EBITDA margin is below Year 1 and should be reviewed.")
A22: =IF(Dashboard!D18>=Dashboard!C18,"Customer count ends above Year 1.","Customer count ends below Year 1 and should be explained.")
A23: Use the Dashboard, Checks, Input_Source_Map, Assumption_Log, and Client_Request_List tabs as the standard client delivery pack.

Sheet Client_Request_List
A1: Client Request List
A2: Tracker for open requests, deliverables, dependencies, and handoff status during an FP&A engagement.
A4: Tracker Summary
A5: Metric | B5: Value | C5: Metric | D5: Value | E5: Metric | F5: Value
A6: Total Requests | B6: =COUNTA(A11:A20) | C6: Done | D6: =COUNTIF(F11:F20,"Done") | E6: Waiting on Client | F6: =COUNTIF(F11:F20,"Waiting on Client")
A7: Open Items | B7: =COUNTIF(F11:F20,"<>Done") | C7: High Priority | D7: =COUNTIF(D11:D20,"High") | E7: In Progress | F7: =COUNTIF(F11:F20,"In Progress")
A9: Detailed Request Tracker
A10: Request ID | B10: Workstream | C10: Request / Deliverable | D10: Priority | E10: Owner | F10: Status | G10: Due Date | H10: Notes
A11: =ROW()-10 | B11: Kickoff | C11: Confirm scope, deliverables, and scenario definitions. | D11: High | E11: FP&A | F11: Done | G11: =Data_Entry!$E$11+3 | H11: Use this as the kickoff checklist in proposals.
A12: =ROW()-10 | B12: Actuals | C12: Provide monthly P&L, balance sheet, and cash flow actuals. | D12: High | E12: Client / Accounting | F12: Waiting on Client | G12: =Data_Entry!$E$11+7 | H12: Needed to replace demo assumptions with real actuals.
A13: =ROW()-10 | B13: Revenue | C13: Share billing export, pipeline, pricing, and churn history. | D13: High | E13: Client / RevOps | F13: In Progress | G13: =Data_Entry!$E$11+10 | H13: Feeds customer, ARPU, churn, and implementation fee drivers.
A14: =ROW()-10 | B14: People | C14: Share payroll register, org chart, and hiring plan. | D14: High | E14: Client / HR | F14: Waiting on Client | G14: =Data_Entry!$E$11+10 | H14: Needed to validate opening HC and salary assumptions.
A15: =ROW()-10 | B15: Working Capital | C15: Confirm AR aging, AP aging, DSO, and DPO targets. | D15: Medium | E15: Client / Controller | F15: Not Started | G15: =Data_Entry!$E$11+12 | H15: Required for CF and BS accuracy.
A16: =ROW()-10 | B16: Treasury | C16: Provide debt agreements, draw schedule, and repayment plan. | D16: Medium | E16: Client / Treasury | F16: Not Started | G16: =Data_Entry!$E$11+14 | H16: Used for debt balance and interest expense.
A17: =ROW()-10 | B17: Capex | C17: Provide fixed asset rollforward and capex plan. | D17: Medium | E17: Client / Accounting | F17: Not Started | G17: =Data_Entry!$E$11+14 | H17: Used for depreciation and PP&E build.
A18: =ROW()-10 | B18: Review | C18: Review Base / Upside / Downside assumptions with management. | D18: High | E18: FP&A + CFO | F18: Not Started | G18: =Data_Entry!$E$11+18 | H18: Use before finalizing the scenario pack.
A19: =ROW()-10 | B19: QA | C19: Run checks and confirm that outputs tie across the model. | D19: High | E19: FP&A | F19: Not Started | G19: =Data_Entry!$E$11+20 | H19: Checks tab should be clean before handoff.
A20: =ROW()-10 | B20: Handoff | C20: Deliver final model, executive summary, and walkthrough. | D20: Medium | E20: FP&A | F20: Not Started | G20: =Data_Entry!$E$11+21 | H20: Final client package.

Sheet Assumption_Log
A1: Assumption Log
A2: Audit-friendly log of key model drivers, linked to Data_Entry and ready for client review.
A4: Review Summary
A5: Metric | B5: Value | C5: Metric | D5: Value | E5: Metric | F5: Value
A6: Logged Assumptions | B6: =COUNTA(B11:B26) | C6: Reviewed | D6: =COUNTIF(J11:J26,"Reviewed") | E6: Approved | F6: =COUNTIF(J11:J26,"Approved")
A7: Selected Scenario | B7: =Data_Entry!$B$5 | C7: Model Start | D7: =Dashboard!$B$4 | E7: Use | F7: Purpose: client assumption review, challenge session, and sign-off log.
A9: Detailed Assumption Register
A10: ID | B10: Driver / Assumption | C10: Base | D10: Upside | E10: Downside | F10: Selected | G10: Unit | H10: Rationale / Modeling Use | I10: Primary Source / Owner | J10: Review Status | K10: Reviewer Notes
A11: 1 | B11: Monthly New Customers | C11: =Data_Entry!B20 | D11: =Data_Entry!C20 | E11: =Data_Entry!D20 | F11: =Data_Entry!E20 | G11: customers | H11: Driver for customer cohort model. Feeds into ending customer count, subscription revenue, and implementation revenue each month. Sensitivity: ±10 customers/month ≈ ±$36K annual revenue (Base ARPU). | I11: CRM pipeline / Sales leadership | J11: Ready for review | K11: — Pending client sign-off —
A12: 2 | B12: Monthly Churn % | C12: =Data_Entry!B21 | D12: =Data_Entry!C21 | E12: =Data_Entry!D21 | F12: =Data_Entry!E21 | G12: % | H12: Applied to beginning-of-period customers. Net Revenue Retention = (1 - churn%) × 12 annualized. Base 2% monthly = ~21.5% annual churn. Sensitive driver — 0.5% change affects revenue by ~3%. | I12: Billing / retention report | J12: Ready for review | K12: — Pending client sign-off —
A13: 3 | B13: Starting ARPU | C13: =Data_Entry!B22 | D13: =Data_Entry!C22 | E13: =Data_Entry!D22 | F13: =Data_Entry!E22 | G13: USD | H13: Anchor for monthly subscription revenue. Compounds monthly at Annual Price Uplift / 12. Should reconcile to billing system ARR ÷ customer count. | I13: Billing export / pricing file | J13: Ready for review | K13: — Pending client sign-off —
A14: 4 | B14: Annual Price Uplift % | C14: =Data_Entry!B23 | D14: =Data_Entry!C23 | E14: =Data_Entry!D23 | F14: =Data_Entry!E23 | G14: % | H14: Applied monthly as (1 + rate/12) compounding. Base 3% = $9/month uplift on $300 ARPU in year 1. Verify against contract renewal terms and pricing strategy. | I14: Pricing strategy / management guidance | J14: Ready for review | K14: — Pending client sign-off —
A15: 5 | B15: Implementation Fee / New Customer | C15: =Data_Entry!B24 | D15: =Data_Entry!C24 | E15: =Data_Entry!D24 | F15: =Data_Entry!E24 | G15: USD | H15: One-time fee per new customer. Revenue recognized in month of onboarding. Directly multiplied by monthly new customer adds. High impact in early growth phase. | I15: Contracts / sales order form | J15: Ready for review | K15: — Pending client sign-off —
A16: 6 | B16: COGS % Revenue | C16: =Data_Entry!B25 | D16: =Data_Entry!C25 | E16: =Data_Entry!D25 | F16: =Data_Entry!E25 | G16: % | H16: Blended direct delivery cost rate. Covers hosting, support, and variable COGS. Applied to total revenue monthly. Gross margin = 1 - COGS%. Base: 85% gross margin. | I16: Historical P&L / unit economics | J16: Ready for review | K16: — Pending client sign-off —
A17: 7 | B17: Benefits % Payroll | C17: =Data_Entry!B26 | D17: =Data_Entry!C26 | E17: =Data_Entry!D26 | F17: =Data_Entry!E26 | G17: % | H17: Loaded on top of base salary to capture payroll taxes, health, and benefits. Applied uniformly across all departments. Base 18% is conservative — typical SaaS range 15–25%. | I17: Payroll burden / benefits policy | J17: Ready for review | K17: — Pending client sign-off —
A18: 8 | B18: Tax Rate | C18: =Data_Entry!B27 | D18: =Data_Entry!C27 | E18: =Data_Entry!D27 | F18: =Data_Entry!E27 | G18: % | H18: Effective planning rate applied to EBT when positive (MAX(0, EBT × rate)). Tax is only recognized on profit — no negative tax in loss months. Verify with tax advisor. | I18: Tax planning / historical ETR | J18: Ready for review | K18: — Pending client sign-off —
A19: 9 | B19: DSO | C19: =Data_Entry!B28 | D19: =Data_Entry!C28 | E19: =Data_Entry!D28 | F19: =Data_Entry!E28 | G19: days | H19: Days sales outstanding. Used to calculate AR balance = Revenue × DSO / 30. Drives working capital needs. Lower DSO = faster collections = better cash conversion. | I19: AR aging / collections trend | J19: Ready for review | K19: — Pending client sign-off —
A20: 10 | B20: DPO | C20: =Data_Entry!B29 | D20: =Data_Entry!C29 | E20: =Data_Entry!D29 | F20: =Data_Entry!E29 | G20: days | H20: Days payable outstanding. Used to calculate AP balance = COGS × DPO / 30. Higher DPO = slower payments = more supplier financing. Should align with vendor agreements. | I20: AP aging / payment cadence | J20: Ready for review | K20: — Pending client sign-off —
A21: 11 | B21: Interest Rate | C21: =Data_Entry!B30 | D21: =Data_Entry!C30 | E21: =Data_Entry!D30 | F21: =Data_Entry!E30 | G21: % | H21: Annual rate applied to average opening debt balance monthly (rate / 12). Represents blended cost of all debt facilities. Update when refinancing or drawing new facilities. | I21: Debt agreement / treasury plan | J21: Ready for review | K21: — Pending client sign-off —
A22: 12 | B22: Depreciation Life (months) | C22: =Data_Entry!B31 | D22: =Data_Entry!C31 | E22: =Data_Entry!D31 | F22: =Data_Entry!E31 | G22: months | H22: Straight-line depreciation over this period (months). Depreciation = Capex / Life per month. 36 months = 3-year useful life — typical for SaaS infrastructure and equipment. | I22: Accounting policy | J22: Ready for review | K22: — Pending client sign-off —
A23: 13 | B23: Capex % Revenue | C23: =Data_Entry!B32 | D23: =Data_Entry!C32 | E23: =Data_Entry!D32 | F23: =Data_Entry!E32 | G23: % | H23: Capital expenditure as a percent of revenue. Low for pure SaaS (asset-light). Drives Capex schedule, depreciation, and PP&E on balance sheet. Verify against capex plan. | I23: Capex plan / board budget | J23: Ready for review | K23: — Pending client sign-off —
A24: 14 | B24: Marketing Programs % Revenue | C24: =Data_Entry!B43 | D24: =Data_Entry!C43 | E24: =Data_Entry!D43 | F24: =Data_Entry!E43 | G24: % | H24: Demand generation spend as % of revenue. Separate from payroll-based marketing salaries. Covers paid acquisition, events, and campaigns. Higher in Upside to fund growth. | I24: Marketing budget / demand plan | J24: Ready for review | K24: — Pending client sign-off —
A25: 15 | B25: Travel % Revenue | C25: =Data_Entry!B46 | D25: =Data_Entry!C46 | E25: =Data_Entry!D46 | F25: =Data_Entry!E46 | G25: % | H25: Travel and entertainment as % of revenue. Scales with revenue growth. Base 1% is typical for B2B SaaS at this stage. Adjust for remote-first or field-heavy teams. | I25: Historical spend / travel policy | J25: Ready for review | K25: — Pending client sign-off —
A26: 16 | B26: Sales Salary | C26: =Data_Entry!B38 | D26: =Data_Entry!C38 | E26: =Data_Entry!D38 | F26: =Data_Entry!E38 | G26: USD / yr | H26: Average annual base salary for Sales team. Used with Benefits % to compute fully loaded monthly payroll per FTE. Multiply by headcount and divide by 12 for monthly expense. | I26: Payroll / comp plan | J26: Ready for review | K26: — Pending client sign-off —

Sheet Control
B1: Control Panel
A2: Select the scenario and review the color coding used in the file.
B4: Model Controls
B5: Scenario | C5: Selected | D5: Notes
B6: Base / Upside / Downside | C6: =Data_Entry!$B$5 | D6: Change the scenario on Data_Entry to update the full model.
B8: Color legend
B9: Input / editable | C9: Sample
B10: Formula | C10: Sample
B11: Cross-sheet link | C11: Sample
B12: Static / note | C12: Sample
B13: Flag / review | C13: Sample
B16: Model Map
B17: Sheet | C17: Purpose
B18: Data_Entry | C18: Single place for scenario, assumptions, hiring plan, and debt inputs
B19: Revenue | C19: Customers, ARPU, revenue & gross profit
B20: Headcount | C20: Hiring plan and payroll expense
B21: Opex | C21: Non-payroll operating expenses
B22: Working_Capital | C22: AR / AP balances and deltas
B23: Capex | C23: Capex and depreciation
B24: Debt | C24: Debt balance and interest
B25: IS / CF / BS | C25: 3 integrated statements
B26: Dashboard / Checks | C26: KPI snapshot and QA tests

Sheet Assumptions
B1: Assumptions & Scenario Drivers
A2: Illustrative assumptions. Replace these with real client data during live engagement.
B4: Core Assumptions
B5: Metric | C5: Base | D5: Upside | E5: Downside | F5: Selected | G5: Units | H5: Notes
B6: Model Start Date | C6: =Data_Entry!$B$11 | D6: =Data_Entry!$C$11 | E6: =Data_Entry!$D$11 | F6: =Data_Entry!$E$11 | G6: date | H6: Timeline start for monthly forecast
B7: Initial Cash | C7: =Data_Entry!$B$12 | D7: =Data_Entry!$C$12 | E7: =Data_Entry!$D$12 | F7: =Data_Entry!$E$12 | G7: USD | H7: Opening cash on balance sheet
B8: Initial AR | C8: =Data_Entry!$B$13 | D8: =Data_Entry!$C$13 | E8: =Data_Entry!$D$13 | F8: =Data_Entry!$E$13 | G8: USD | H8: Opening accounts receivable
B9: Initial Net PP&E | C9: =Data_Entry!$B$14 | D9: =Data_Entry!$C$14 | E9: =Data_Entry!$D$14 | F9: =Data_Entry!$E$14 | G9: USD | H9: Opening net fixed assets
B10: Initial AP | C10: =Data_Entry!$B$15 | D10: =Data_Entry!$C$15 | E10: =Data_Entry!$D$15 | F10: =Data_Entry!$E$15 | G10: USD | H10: Opening accounts payable
B11: Initial Debt | C11: =Data_Entry!$B$16 | D11: =Data_Entry!$C$16 | E11: =Data_Entry!$D$16 | F11: =Data_Entry!$E$16 | G11: USD | H11: Opening interest-bearing debt
B12: Share Capital | C12: =Data_Entry!$B$17 | D12: =Data_Entry!$C$17 | E12: =Data_Entry!$D$17 | F12: =Data_Entry!$E$17 | G12: USD | H12: Static equity capital
B13: Opening Retained Earnings | C13: =Data_Entry!$B$18 | D13: =Data_Entry!$C$18 | E13: =Data_Entry!$D$18 | F13: =Data_Entry!$E$18 | G13: USD | H13: Opening retained earnings
B14: Beginning Customers | C14: =Data_Entry!$B$19 | D14: =Data_Entry!$C$19 | E14: =Data_Entry!$D$19 | F14: =Data_Entry!$E$19 | G14: customers | H14: Opening subscriber count
B15: Monthly New Customers | C15: =Data_Entry!$B$20 | D15: =Data_Entry!$C$20 | E15: =Data_Entry!$D$20 | F15: =Data_Entry!$E$20 | G15: customers | H15: Average monthly gross adds
B16: Monthly Churn % | C16: =Data_Entry!$B$21 | D16: =Data_Entry!$C$21 | E16: =Data_Entry!$D$21 | F16: =Data_Entry!$E$21 | G16: % | H16: Monthly customer churn rate
B17: Starting ARPU | C17: =Data_Entry!$B$22 | D17: =Data_Entry!$C$22 | E17: =Data_Entry!$D$22 | F17: =Data_Entry!$E$22 | G17: USD | H17: Average revenue per customer per month
B18: Annual Price Uplift % | C18: =Data_Entry!$B$23 | D18: =Data_Entry!$C$23 | E18: =Data_Entry!$D$23 | F18: =Data_Entry!$E$23 | G18: % | H18: Annual ARPU increase
B19: Implementation Fee / New Customer | C19: =Data_Entry!$B$24 | D19: =Data_Entry!$C$24 | E19: =Data_Entry!$D$24 | F19: =Data_Entry!$E$24 | G19: USD | H19: One-time onboarding fee
B20: COGS % Revenue | C20: =Data_Entry!$B$25 | D20: =Data_Entry!$C$25 | E20: =Data_Entry!$D$25 | F20: =Data_Entry!$E$25 | G20: % | H20: Direct service delivery cost as % of revenue
B21: Benefits % Payroll | C21: =Data_Entry!$B$26 | D21: =Data_Entry!$C$26 | E21: =Data_Entry!$D$26 | F21: =Data_Entry!$E$26 | G21: % | H21: Payroll burden & benefits
B22: Tax Rate | C22: =Data_Entry!$B$27 | D22: =Data_Entry!$C$27 | E22: =Data_Entry!$D$27 | F22: =Data_Entry!$E$27 | G22: % | H22: Effective corporate tax rate
B23: DSO | C23: =Data_Entry!$B$28 | D23: =Data_Entry!$C$28 | E23: =Data_Entry!$D$28 | F23: =Data_Entry!$E$28 | G23: days | H23: Average collection period
B24: DPO | C24: =Data_Entry!$B$29 | D24: =Data_Entry!$C$29 | E24: =Data_Entry!$D$29 | F24: =Data_Entry!$E$29 | G24: days | H24: Average payment period
B25: Interest Rate | C25: =Data_Entry!$B$30 | D25: =Data_Entry!$C$30 | E25: =Data_Entry!$D$30 | F25: =Data_Entry!$E$30 | G25: % | H25: Average annual debt cost
B26: Depreciation Life (months) | C26: =Data_Entry!$B$31 | D26: =Data_Entry!$C$31 | E26: =Data_Entry!$D$31 | F26: =Data_Entry!$E$31 | G26: months | H26: Straight-line useful life
B27: Capex % Revenue | C27: =Data_Entry!$B$32 | D27: =Data_Entry!$C$32 | E27: =Data_Entry!$D$32 | F27: =Data_Entry!$E$32 | G27: % | H27: Capital spend as % of revenue
B28: Sales Opening HC | C28: =Data_Entry!$B$33 | D28: =Data_Entry!$C$33 | E28: =Data_Entry!$D$33 | F28: =Data_Entry!$E$33 | G28: FTE | H28: Opening sales team headcount
B29: Marketing Opening HC | C29: =Data_Entry!$B$34 | D29: =Data_Entry!$C$34 | E29: =Data_Entry!$D$34 | F29: =Data_Entry!$E$34 | G29: FTE | H29: Opening marketing headcount
B30: R&D Opening HC | C30: =Data_Entry!$B$35 | D30: =Data_Entry!$C$35 | E30: =Data_Entry!$D$35 | F30: =Data_Entry!$E$35 | G30: FTE | H30: Opening R&D headcount
B31: G&A Opening HC | C31: =Data_Entry!$B$36 | D31: =Data_Entry!$C$36 | E31: =Data_Entry!$D$36 | F31: =Data_Entry!$E$36 | G31: FTE | H31: Opening G&A headcount
B32: Customer Success Opening HC | C32: =Data_Entry!$B$37 | D32: =Data_Entry!$C$37 | E32: =Data_Entry!$D$37 | F32: =Data_Entry!$E$37 | G32: FTE | H32: Opening CS headcount
B33: Sales Salary | C33: =Data_Entry!$B$38 | D33: =Data_Entry!$C$38 | E33: =Data_Entry!$D$38 | F33: =Data_Entry!$E$38 | G33: USD/yr | H33: Average annual fully loaded base salary
B34: Marketing Salary | C34: =Data_Entry!$B$39 | D34: =Data_Entry!$C$39 | E34: =Data_Entry!$D$39 | F34: =Data_Entry!$E$39 | G34: USD/yr | H34: Average annual fully loaded base salary
B35: R&D Salary | C35: =Data_Entry!$B$40 | D35: =Data_Entry!$C$40 | E35: =Data_Entry!$D$40 | F35: =Data_Entry!$E$40 | G35: USD/yr | H35: Average annual fully loaded base salary
B36: G&A Salary | C36: =Data_Entry!$B$41 | D36: =Data_Entry!$C$41 | E36: =Data_Entry!$D$41 | F36: =Data_Entry!$E$41 | G36: USD/yr | H36: Average annual fully loaded base salary
B37: Customer Success Salary | C37: =Data_Entry!$B$42 | D37: =Data_Entry!$C$42 | E37: =Data_Entry!$D$42 | F37: =Data_Entry!$E$42 | G37: USD/yr | H37: Average annual fully loaded base salary
B38: Marketing Programs % Revenue | C38: =Data_Entry!$B$43 | D38: =Data_Entry!$C$43 | E38: =Data_Entry!$D$43 | F38: =Data_Entry!$E$43 | G38: % | H38: Demand generation spend as % of revenue
B39: Software / month | C39: =Data_Entry!$B$44 | D39: =Data_Entry!$C$44 | E39: =Data_Entry!$D$44 | F39: =Data_Entry!$E$44 | G39: USD | H39: Core SaaS tools and subscriptions
B40: Rent / month | C40: =Data_Entry!$B$45 | D40: =Data_Entry!$C$45 | E40: =Data_Entry!$D$45 | F40: =Data_Entry!$E$45 | G40: USD | H40: Office / facilities
B41: Travel % Revenue | C41: =Data_Entry!$B$46 | D41: =Data_Entry!$C$46 | E41: =Data_Entry!$D$46 | F41: =Data_Entry!$E$46 | G41: % | H41: Travel and entertainment as % of revenue
...

Sheet Revenue
A1: Revenue Schedule
A2: Customers -> ARPU -> revenue -> COGS -> gross profit
A3: Monthly Revenue Model
B4: =Assumptions!$F$6 | C4: =DATE(YEAR(B4),MONTH(B4)+1,1) | D4: =DATE(YEAR(C4),MONTH(C4)+1,1) | E4: =DATE(YEAR(D4),MONTH(D4)+1,1) | F4: =DATE(YEAR(E4),MONTH(E4)+1,1) | G4: =DATE(YEAR(F4),MONTH(F4)+1,1) | H4: =DATE(YEAR(G4),MONTH(G4)+1,1) | I4: =DATE(YEAR(H4),MONTH(H4)+1,1) | J4: =DATE(YEAR(I4),MONTH(I4)+1,1) | ... Y4: =DATE(YEAR(X4),MONTH(X4)+1,1)
A6: Beginning Customers | B6: =Assumptions!$F$14 | C6: =B10 | D6: =C10 | E6: =D10 | F6: =E10 | G6: =F10 | H6: =G10 | I6: =H10 | J6: =I10 | ... Y6: =X10
A7: New Customers | B7: =IF(ISNUMBER(Data_Entry!B52),Data_Entry!B52,Assumptions!$F$15) | C7: =IF(ISNUMBER(Data_Entry!C52),Data_Entry!C52,Assumptions!$F$15) | D7: =IF(ISNUMBER(Data_Entry!D52),Data_Entry!D52,Assumptions!$F$15) | E7: =IF(ISNUMBER(Data_Entry!E52),Data_Entry!E52,Assumptions!$F$15) | F7: =IF(ISNUMBER(Data_Entry!F52),Data_Entry!F52,Assumptions!$F$15) | G7: =IF(ISNUMBER(Data_Entry!G52),Data_Entry!G52,Assumptions!$F$15) | H7: =IF(ISNUMBER(Data_Entry!H52),Data_Entry!H52,Assumptions!$F$15) | I7: =IF(ISNUMBER(Data_Entry!I52),Data_Entry!I52,Assumptions!$F$15) | ... Y7: =IF(ISNUMBER(Data_Entry!Y52),Data_Entry!Y52,Assumptions!$F$15)
A8: Churn % | B8: =Assumptions!$F$16 | C8: =Assumptions!$F$16 | D8: =Assumptions!$F$16 | E8: =Assumptions!$F$16 | F8: =Assumptions!$F$16 | G8: =Assumptions!$F$16 | H8: =Assumptions!$F$16 | I8: =Assumptions!$F$16 | ... Y8: =Assumptions!$F$16
A9: Churned Customers | B9: =B6*B8 | C9: =C6*C8 | D9: =D6*D8 | E9: =E6*E8 | F9: =F6*F8 | G9: =G6*G8 | H9: =H6*H8 | I9: =I6*I8 | ... Y9: =Y6*Y8
A10: Ending Customers | B10: =B6+B7-B9 | C10: =C6+C7-C9 | D10: =D6+D7-D9 | E10: =E6+E7-E9 | F10: =F6+F7-F9 | G10: =G6+G7-G9 | H10: =H6+H7-H9 | I10: =I6+I7-I9 | ... Y10: =Y6+Y7-Y9
A11: ARPU | B11: =Assumptions!$F$17 | C11: =B11*(1+Assumptions!$F$18/12) | D11: =C11*(1+Assumptions!$F$18/12) | E11: =D11*(1+Assumptions!$F$18/12) | F11: =E11*(1+Assumptions!$F$18/12) | G11: =F11*(1+Assumptions!$F$18/12) | H11: =G11*(1+Assumptions!$F$18/12) | I11: =H11*(1+Assumptions!$F$18/12) | J11: =I11*(1+Assumptions!$F$18/12) | ... Y11: =X11*(1+Assumptions!$F$18/12)
A12: Subscription Revenue | B12: =((B6+B10)/2)*B11 | C12: =((C6+C10)/2)*C11 | D12: =((D6+D10)/2)*D11 | E12: =((E6+E10)/2)*E11 | F12: =((F6+F10)/2)*F11 | G12: =((G6+G10)/2)*G11 | H12: =((H6+H10)/2)*H11 | I12: =((I6+I10)/2)*I11 | ... Y12: =((Y6+Y10)/2)*Y11
A13: Implementation Fee / New Cust | B13: =Assumptions!$F$19 | C13: =Assumptions!$F$19 | D13: =Assumptions!$F$19 | E13: =Assumptions!$F$19 | F13: =Assumptions!$F$19 | G13: =Assumptions!$F$19 | H13: =Assumptions!$F$19 | I13: =Assumptions!$F$19 | ... Y13: =Assumptions!$F$19
A14: Implementation Revenue | B14: =B7*B13 | C14: =C7*C13 | D14: =D7*D13 | E14: =E7*E13 | F14: =F7*F13 | G14: =G7*G13 | H14: =H7*H13 | I14: =I7*I13 | ... Y14: =Y7*Y13
A15: Total Revenue | B15: =SUM(B12:B14) | C15: =SUM(C12:C14) | D15: =SUM(D12:D14) | E15: =SUM(E12:E14) | F15: =SUM(F12:F14) | G15: =SUM(G12:G14) | H15: =SUM(H12:H14) | I15: =SUM(I12:I14) | ... Y15: =SUM(Y12:Y14)
A17: COGS % | B17: =Assumptions!$F$20 | C17: =Assumptions!$F$20 | D17: =Assumptions!$F$20 | E17: =Assumptions!$F$20 | F17: =Assumptions!$F$20 | G17: =Assumptions!$F$20 | H17: =Assumptions!$F$20 | I17: =Assumptions!$F$20 | ... Y17: =Assumptions!$F$20
A18: COGS | B18: =B15*B17 | C18: =C15*C17 | D18: =D15*D17 | E18: =E15*E17 | F18: =F15*F17 | G18: =G15*G17 | H18: =H15*H17 | I18: =I15*I17 | ... Y18: =Y15*Y17
A19: Gross Profit | B19: =B15-B18 | C19: =C15-C18 | D19: =D15-D18 | E19: =E15-E18 | F19: =F15-F18 | G19: =G15-G18 | H19: =H15-H18 | I19: =I15-I18 | ... Y19: =Y15-Y18

Sheet Headcount
A1: Headcount & Payroll
A2: Editable hiring plan (blue/yellow) feeding monthly payroll expense.
A3: Department Schedules
B4: =Assumptions!$F$6 | C4: =DATE(YEAR(B4),MONTH(B4)+1,1) | D4: =DATE(YEAR(C4),MONTH(C4)+1,1) | E4: =DATE(YEAR(D4),MONTH(D4)+1,1) | F4: =DATE(YEAR(E4),MONTH(E4)+1,1) | G4: =DATE(YEAR(F4),MONTH(F4)+1,1) | H4: =DATE(YEAR(G4),MONTH(G4)+1,1) | I4: =DATE(YEAR(H4),MONTH(H4)+1,1) | J4: =DATE(YEAR(I4),MONTH(I4)+1,1) | ... Y4: =DATE(YEAR(X4),MONTH(X4)+1,1)
A6: Sales
A7: Opening HC | B7: =Assumptions!$F$28 | C7: =B10 | D7: =C10 | E7: =D10 | F7: =E10 | G7: =F10 | H7: =G10 | I7: =H10 | J7: =I10 | ... Y7: =X10
A8: Hires | B8: =Data_Entry!B52 | C8: =Data_Entry!C52 | D8: =Data_Entry!D52 | E8: =Data_Entry!E52 | F8: =Data_Entry!F52 | G8: =Data_Entry!G52 | H8: =Data_Entry!H52 | I8: =Data_Entry!I52 | ... Y8: =Data_Entry!Y52
A9: Terms | B9: =Data_Entry!B53 | C9: =Data_Entry!C53 | D9: =Data_Entry!D53 | E9: =Data_Entry!E53 | F9: =Data_Entry!F53 | G9: =Data_Entry!G53 | H9: =Data_Entry!H53 | I9: =Data_Entry!I53 | ... Y9: =Data_Entry!Y53
A10: Ending HC | B10: =B7+B8-B9 | C10: =C7+C8-C9 | D10: =D7+D8-D9 | E10: =E7+E8-E9 | F10: =F7+F8-F9 | G10: =G7+G8-G9 | H10: =H7+H8-H9 | I10: =I7+I8-I9 | ... Y10: =Y7+Y8-Y9
A11: Average HC | B11: =(B7+B10)/2 | C11: =(C7+C10)/2 | D11: =(D7+D10)/2 | E11: =(E7+E10)/2 | F11: =(F7+F10)/2 | G11: =(G7+G10)/2 | H11: =(H7+H10)/2 | I11: =(I7+I10)/2 | ... Y11: =(Y7+Y10)/2
A12: Salary Expense | B12: =B11*Assumptions!$F$33/12*(1+Assumptions!$F$21) | C12: =C11*Assumptions!$F$33/12*(1+Assumptions!$F$21) | D12: =D11*Assumptions!$F$33/12*(1+Assumptions!$F$21) | E12: =E11*Assumptions!$F$33/12*(1+Assumptions!$F$21) | F12: =F11*Assumptions!$F$33/12*(1+Assumptions!$F$21) | G12: =G11*Assumptions!$F$33/12*(1+Assumptions!$F$21) | H12: =H11*Assumptions!$F$33/12*(1+Assumptions!$F$21) | I12: =I11*Assumptions!$F$33/12*(1+Assumptions!$F$21) | ... Y12: =Y11*Assumptions!$F$33/12*(1+Assumptions!$F$21)
A15: Marketing
A16: Opening HC | B16: =Assumptions!$F$29 | C16: =B19 | D16: =C19 | E16: =D19 | F16: =E19 | G16: =F19 | H16: =G19 | I16: =H19 | J16: =I19 | ... Y16: =X19
A17: Hires | B17: =Data_Entry!B54 | C17: =Data_Entry!C54 | D17: =Data_Entry!D54 | E17: =Data_Entry!E54 | F17: =Data_Entry!F54 | G17: =Data_Entry!G54 | H17: =Data_Entry!H54 | I17: =Data_Entry!I54 | ... Y17: =Data_Entry!Y54
A18: Terms | B18: =Data_Entry!B55 | C18: =Data_Entry!C55 | D18: =Data_Entry!D55 | E18: =Data_Entry!E55 | F18: =Data_Entry!F55 | G18: =Data_Entry!G55 | H18: =Data_Entry!H55 | I18: =Data_Entry!I55 | ... Y18: =Data_Entry!Y55
A19: Ending HC | B19: =B16+B17-B18 | C19: =C16+C17-C18 | D19: =D16+D17-D18 | E19: =E16+E17-E18 | F19: =F16+F17-F18 | G19: =G16+G17-G18 | H19: =H16+H17-H18 | I19: =I16+I17-I18 | ... Y19: =Y16+Y17-Y18
A20: Average HC | B20: =(B16+B19)/2 | C20: =(C16+C19)/2 | D20: =(D16+D19)/2 | E20: =(E16+E19)/2 | F20: =(F16+F19)/2 | G20: =(G16+G19)/2 | H20: =(H16+H19)/2 | I20: =(I16+I19)/2 | ... Y20: =(Y16+Y19)/2
A21: Salary Expense | B21: =B20*Assumptions!$F$34/12*(1+Assumptions!$F$21) | C21: =C20*Assumptions!$F$34/12*(1+Assumptions!$F$21) | D21: =D20*Assumptions!$F$34/12*(1+Assumptions!$F$21) | E21: =E20*Assumptions!$F$34/12*(1+Assumptions!$F$21) | F21: =F20*Assumptions!$F$34/12*(1+Assumptions!$F$21) | G21: =G20*Assumptions!$F$34/12*(1+Assumptions!$F$21) | H21: =H20*Assumptions!$F$34/12*(1+Assumptions!$F$21) | I21: =I20*Assumptions!$F$34/12*(1+Assumptions!$F$21) | ... Y21: =Y20*Assumptions!$F$34/12*(1+Assumptions!$F$21)
A24: R&D
A25: Opening HC | B25: =Assumptions!$F$30 | C25: =B28 | D25: =C28 | E25: =D28 | F25: =E28 | G25: =F28 | H25: =G28 | I25: =H28 | J25: =I28 | ... Y25: =X28
A26: Hires | B26: =Data_Entry!B56 | C26: =Data_Entry!C56 | D26: =Data_Entry!D56 | E26: =Data_Entry!E56 | F26: =Data_Entry!F56 | G26: =Data_Entry!G56 | H26: =Data_Entry!H56 | I26: =Data_Entry!I56 | ... Y26: =Data_Entry!Y56
A27: Terms | B27: =Data_Entry!B57 | C27: =Data_Entry!C57 | D27: =Data_Entry!D57 | E27: =Data_Entry!E57 | F27: =Data_Entry!F57 | G27: =Data_Entry!G57 | H27: =Data_Entry!H57 | I27: =Data_Entry!I57 | ... Y27: =Data_Entry!Y57
A28: Ending HC | B28: =B25+B26-B27 | C28: =C25+C26-C27 | D28: =D25+D26-D27 | E28: =E25+E26-E27 | F28: =F25+F26-F27 | G28: =G25+G26-G27 | H28: =H25+H26-H27 | I28: =I25+I26-I27 | ... Y28: =Y25+Y26-Y27
A29: Average HC | B29: =(B25+B28)/2 | C29: =(C25+C28)/2 | D29: =(D25+D28)/2 | E29: =(E25+E28)/2 | F29: =(F25+F28)/2 | G29: =(G25+G28)/2 | H29: =(H25+H28)/2 | I29: =(I25+I28)/2 | ... Y29: =(Y25+Y28)/2
A30: Salary Expense | B30: =B29*Assumptions!$F$35/12*(1+Assumptions!$F$21) | C30: =C29*Assumptions!$F$35/12*(1+Assumptions!$F$21) | D30: =D29*Assumptions!$F$35/12*(1+Assumptions!$F$21) | E30: =E29*Assumptions!$F$35/12*(1+Assumptions!$F$21) | F30: =F29*Assumptions!$F$35/12*(1+Assumptions!$F$21) | G30: =G29*Assumptions!$F$35/12*(1+Assumptions!$F$21) | H30: =H29*Assumptions!$F$35/12*(1+Assumptions!$F$21) | I30: =I29*Assumptions!$F$35/12*(1+Assumptions!$F$21) | ... Y30: =Y29*Assumptions!$F$35/12*(1+Assumptions!$F$21)
A33: G&A
A34: Opening HC | B34: =Assumptions!$F$31 | C34: =B37 | D34: =C37 | E34: =D37 | F34: =E37 | G34: =F37 | H34: =G37 | I34: =H37 | J34: =I37 | ... Y34: =X37
A35: Hires | B35: =Data_Entry!B58 | C35: =Data_Entry!C58 | D35: =Data_Entry!D58 | E35: =Data_Entry!E58 | F35: =Data_Entry!F58 | G35: =Data_Entry!G58 | H35: =Data_Entry!H58 | I35: =Data_Entry!I58 | ... Y35: =Data_Entry!Y58
A36: Terms | B36: =Data_Entry!B59 | C36: =Data_Entry!C59 | D36: =Data_Entry!D59 | E36: =Data_Entry!E59 | F36: =Data_Entry!F59 | G36: =Data_Entry!G59 | H36: =Data_Entry!H59 | I36: =Data_Entry!I59 | ... Y36: =Data_Entry!Y59
A37: Ending HC | B37: =B34+B35-B36 | C37: =C34+C35-C36 | D37: =D34+D35-D36 | E37: =E34+E35-E36 | F37: =F34+F35-F36 | G37: =G34+G35-G36 | H37: =H34+H35-H36 | I37: =I34+I35-I36 | ... Y37: =Y34+Y35-Y36
A38: Average HC | B38: =(B34+B37)/2 | C38: =(C34+C37)/2 | D38: =(D34+D37)/2 | E38: =(E34+E37)/2 | F38: =(F34+F37)/2 | G38: =(G34+G37)/2 | H38: =(H34+H37)/2 | I38: =(I34+I37)/2 | ... Y38: =(Y34+Y37)/2
A39: Salary Expense | B39: =B38*Assumptions!$F$36/12*(1+Assumptions!$F$21) | C39: =C38*Assumptions!$F$36/12*(1+Assumptions!$F$21) | D39: =D38*Assumptions!$F$36/12*(1+Assumptions!$F$21) | E39: =E38*Assumptions!$F$36/12*(1+Assumptions!$F$21) | F39: =F38*Assumptions!$F$36/12*(1+Assumptions!$F$21) | G39: =G38*Assumptions!$F$36/12*(1+Assumptions!$F$21) | H39: =H38*Assumptions!$F$36/12*(1+Assumptions!$F$21) | I39: =I38*Assumptions!$F$36/12*(1+Assumptions!$F$21) | ... Y39: =Y38*Assumptions!$F$36/12*(1+Assumptions!$F$21)
A42: Customer Success
A43: Opening HC | B43: =Assumptions!$F$32 | C43: =B46 | D43: =C46 | E43: =D46 | F43: =E46 | G43: =F46 | H43: =G46 | I43: =H46 | J43: =I46 | ... Y43: =X46
A44: Hires | B44: =Data_Entry!B60 | C44: =Data_Entry!C60 | D44: =Data_Entry!D60 | E44: =Data_Entry!E60 | F44: =Data_Entry!F60 | G44: =Data_Entry!G60 | H44: =Data_Entry!H60 | I44: =Data_Entry!I60 | ... Y44: =Data_Entry!Y60
A45: Terms | B45: =Data_Entry!B61 | C45: =Data_Entry!C61 | D45: =Data_Entry!D61 | E45: =Data_Entry!E61 | F45: =Data_Entry!F61 | G45: =Data_Entry!G61 | H45: =Data_Entry!H61 | I45: =Data_Entry!I61 | ... Y45: =Data_Entry!Y61
A46: Ending HC | B46: =B43+B44-B45 | C46: =C43+C44-C45 | D46: =D43+D44-D45 | E46: =E43+E44-E45 | F46: =F43+F44-F45 | G46: =G43+G44-G45 | H46: =H43+H44-H45 | I46: =I43+I44-I45 | ... Y46: =Y43+Y44-Y45
A47: Average HC | B47: =(B43+B46)/2 | C47: =(C43+C46)/2 | D47: =(D43+D46)/2 | E47: =(E43+E46)/2 | F47: =(F43+F46)/2 | G47: =(G43+G46)/2 | H47: =(H43+H46)/2 | I47: =(I43+I46)/2 | ... Y47: =(Y43+Y46)/2
A48: Salary Expense | B48: =B47*Assumptions!$F$37/12*(1+Assumptions!$F$21) | C48: =C47*Assumptions!$F$37/12*(1+Assumptions!$F$21) | D48: =D47*Assumptions!$F$37/12*(1+Assumptions!$F$21) | E48: =E47*Assumptions!$F$37/12*(1+Assumptions!$F$21) | F48: =F47*Assumptions!$F$37/12*(1+Assumptions!$F$21) | G48: =G47*Assumptions!$F$37/12*(1+Assumptions!$F$21) | H48: =H47*Assumptions!$F$37/12*(1+Assumptions!$F$21) | I48: =I47*Assumptions!$F$37/12*(1+Assumptions!$F$21) | ... Y48: =Y47*Assumptions!$F$37/12*(1+Assumptions!$F$21)
A51: Headcount Summary
...

Sheet Opex
A1: Operating Expense Schedule
A2: Payroll linked from Headcount; other opex driven by assumptions and revenue.
A3: Monthly Opex
B4: =Assumptions!$F$6 | C4: =DATE(YEAR(B4),MONTH(B4)+1,1) | D4: =DATE(YEAR(C4),MONTH(C4)+1,1) | E4: =DATE(YEAR(D4),MONTH(D4)+1,1) | F4: =DATE(YEAR(E4),MONTH(E4)+1,1) | G4: =DATE(YEAR(F4),MONTH(F4)+1,1) | H4: =DATE(YEAR(G4),MONTH(G4)+1,1) | I4: =DATE(YEAR(H4),MONTH(H4)+1,1) | J4: =DATE(YEAR(I4),MONTH(I4)+1,1) | ... Y4: =DATE(YEAR(X4),MONTH(X4)+1,1)
A6: Payroll Expense | B6: =Headcount!B53 | C6: =Headcount!C53 | D6: =Headcount!D53 | E6: =Headcount!E53 | F6: =Headcount!F53 | G6: =Headcount!G53 | H6: =Headcount!H53 | I6: =Headcount!I53 | ... Y6: =Headcount!Y53
A7: Marketing Programs | B7: =Revenue!B15*Assumptions!$F$38 | C7: =Revenue!C15*Assumptions!$F$38 | D7: =Revenue!D15*Assumptions!$F$38 | E7: =Revenue!E15*Assumptions!$F$38 | F7: =Revenue!F15*Assumptions!$F$38 | G7: =Revenue!G15*Assumptions!$F$38 | H7: =Revenue!H15*Assumptions!$F$38 | I7: =Revenue!I15*Assumptions!$F$38 | ... Y7: =Revenue!Y15*Assumptions!$F$38
A8: Software | B8: =Assumptions!$F$39 | C8: =Assumptions!$F$39 | D8: =Assumptions!$F$39 | E8: =Assumptions!$F$39 | F8: =Assumptions!$F$39 | G8: =Assumptions!$F$39 | H8: =Assumptions!$F$39 | I8: =Assumptions!$F$39 | ... Y8: =Assumptions!$F$39
A9: Rent | B9: =Assumptions!$F$40 | C9: =Assumptions!$F$40 | D9: =Assumptions!$F$40 | E9: =Assumptions!$F$40 | F9: =Assumptions!$F$40 | G9: =Assumptions!$F$40 | H9: =Assumptions!$F$40 | I9: =Assumptions!$F$40 | ... Y9: =Assumptions!$F$40
A10: Travel & Entertainment | B10: =Revenue!B15*Assumptions!$F$41 | C10: =Revenue!C15*Assumptions!$F$41 | D10: =Revenue!D15*Assumptions!$F$41 | E10: =Revenue!E15*Assumptions!$F$41 | F10: =Revenue!F15*Assumptions!$F$41 | G10: =Revenue!G15*Assumptions!$F$41 | H10: =Revenue!H15*Assumptions!$F$41 | I10: =Revenue!I15*Assumptions!$F$41 | ... Y10: =Revenue!Y15*Assumptions!$F$41
A11: Other G&A | B11: =Assumptions!$F$42 | C11: =Assumptions!$F$42 | D11: =Assumptions!$F$42 | E11: =Assumptions!$F$42 | F11: =Assumptions!$F$42 | G11: =Assumptions!$F$42 | H11: =Assumptions!$F$42 | I11: =Assumptions!$F$42 | ... Y11: =Assumptions!$F$42
A12: Total Opex | B12: =SUM(B6:B11) | C12: =SUM(C6:C11) | D12: =SUM(D6:D11) | E12: =SUM(E6:E11) | F12: =SUM(F6:F11) | G12: =SUM(G6:G11) | H12: =SUM(H6:H11) | I12: =SUM(I6:I11) | ... Y12: =SUM(Y6:Y11)

Sheet Working_Capital
A1: Working Capital Schedule
A2: AR / AP balances based on DSO and DPO.
A3: Monthly Working Capital
B4: =Assumptions!$F$6 | C4: =DATE(YEAR(B4),MONTH(B4)+1,1) | D4: =DATE(YEAR(C4),MONTH(C4)+1,1) | E4: =DATE(YEAR(D4),MONTH(D4)+1,1) | F4: =DATE(YEAR(E4),MONTH(E4)+1,1) | G4: =DATE(YEAR(F4),MONTH(F4)+1,1) | H4: =DATE(YEAR(G4),MONTH(G4)+1,1) | I4: =DATE(YEAR(H4),MONTH(H4)+1,1) | J4: =DATE(YEAR(I4),MONTH(I4)+1,1) | ... Y4: =DATE(YEAR(X4),MONTH(X4)+1,1)
A6: Accounts Receivable | B6: =Revenue!B15/30*Assumptions!$F$23 | C6: =Revenue!C15/30*Assumptions!$F$23 | D6: =Revenue!D15/30*Assumptions!$F$23 | E6: =Revenue!E15/30*Assumptions!$F$23 | F6: =Revenue!F15/30*Assumptions!$F$23 | G6: =Revenue!G15/30*Assumptions!$F$23 | H6: =Revenue!H15/30*Assumptions!$F$23 | I6: =Revenue!I15/30*Assumptions!$F$23 | ... Y6: =Revenue!Y15/30*Assumptions!$F$23
A7: AP Base Costs | B7: =Revenue!B18+Opex!B7+Opex!B8+Opex!B9+Opex!B10+Opex!B11 | C7: =Revenue!C18+Opex!C7+Opex!C8+Opex!C9+Opex!C10+Opex!C11 | D7: =Revenue!D18+Opex!D7+Opex!D8+Opex!D9+Opex!D10+Opex!D11 | E7: =Revenue!E18+Opex!E7+Opex!E8+Opex!E9+Opex!E10+Opex!E11 | F7: =Revenue!F18+Opex!F7+Opex!F8+Opex!F9+Opex!F10+Opex!F11 | G7: =Revenue!G18+Opex!G7+Opex!G8+Opex!G9+Opex!G10+Opex!G11 | H7: =Revenue!H18+Opex!H7+Opex!H8+Opex!H9+Opex!H10+Opex!H11 | I7: =Revenue!I18+Opex!I7+Opex!I8+Opex!I9+Opex!I10+Opex!I11 | ... Y7: =Revenue!Y18+Opex!Y7+Opex!Y8+Opex!Y9+Opex!Y10+Opex!Y11
A8: Accounts Payable | B8: =B7/30*Assumptions!$F$24 | C8: =C7/30*Assumptions!$F$24 | D8: =D7/30*Assumptions!$F$24 | E8: =E7/30*Assumptions!$F$24 | F8: =F7/30*Assumptions!$F$24 | G8: =G7/30*Assumptions!$F$24 | H8: =H7/30*Assumptions!$F$24 | I8: =I7/30*Assumptions!$F$24 | ... Y8: =Y7/30*Assumptions!$F$24
A9: Change in AR | B9: =B6-Assumptions!$F$8 | C9: =C6-B6 | D9: =D6-C6 | E9: =E6-D6 | F9: =F6-E6 | G9: =G6-F6 | H9: =H6-G6 | I9: =I6-H6 | J9: =J6-I6 | ... Y9: =Y6-X6
A10: Change in AP | B10: =B8-Assumptions!$F$10 | C10: =C8-B8 | D10: =D8-C8 | E10: =E8-D8 | F10: =F8-E8 | G10: =G8-F8 | H10: =H8-G8 | I10: =I8-H8 | J10: =J8-I8 | ... Y10: =Y8-X8

Sheet Capex
A1: Capex & Depreciation
A2: Capex driven as % of revenue with straight-line depreciation.
A3: Monthly Capex
B4: =Assumptions!$F$6 | C4: =DATE(YEAR(B4),MONTH(B4)+1,1) | D4: =DATE(YEAR(C4),MONTH(C4)+1,1) | E4: =DATE(YEAR(D4),MONTH(D4)+1,1) | F4: =DATE(YEAR(E4),MONTH(E4)+1,1) | G4: =DATE(YEAR(F4),MONTH(F4)+1,1) | H4: =DATE(YEAR(G4),MONTH(G4)+1,1) | I4: =DATE(YEAR(H4),MONTH(H4)+1,1) | J4: =DATE(YEAR(I4),MONTH(I4)+1,1) | ... Y4: =DATE(YEAR(X4),MONTH(X4)+1,1)
A6: Opening Net PP&E | B6: =Assumptions!$F$9 | C6: =B9 | D6: =C9 | E6: =D9 | F6: =E9 | G6: =F9 | H6: =G9 | I6: =H9 | J6: =I9 | ... Y6: =X9
A7: Capex | B7: =Revenue!B15*Assumptions!$F$27 | C7: =Revenue!C15*Assumptions!$F$27 | D7: =Revenue!D15*Assumptions!$F$27 | E7: =Revenue!E15*Assumptions!$F$27 | F7: =Revenue!F15*Assumptions!$F$27 | G7: =Revenue!G15*Assumptions!$F$27 | H7: =Revenue!H15*Assumptions!$F$27 | I7: =Revenue!I15*Assumptions!$F$27 | ... Y7: =Revenue!Y15*Assumptions!$F$27
A8: Depreciation | B8: =SUM(B7:B7)/Assumptions!$F$26 | C8: =SUM(B7:C7)/Assumptions!$F$26 | D8: =SUM(B7:D7)/Assumptions!$F$26 | E8: =SUM(B7:E7)/Assumptions!$F$26 | F8: =SUM(B7:F7)/Assumptions!$F$26 | G8: =SUM(B7:G7)/Assumptions!$F$26 | H8: =SUM(B7:H7)/Assumptions!$F$26 | I8: =SUM(B7:I7)/Assumptions!$F$26 | J8: =SUM(B7:J7)/Assumptions!$F$26 | K8: =SUM(B7:K7)/Assumptions!$F$26 | L8: =SUM(B7:L7)/Assumptions!$F$26 | M8: =SUM(B7:M7)/Assumptions!$F$26 | N8: =SUM(B7:N7)/Assumptions!$F$26 | O8: =SUM(B7:O7)/Assumptions!$F$26 | P8: =SUM(B7:P7)/Assumptions!$F$26 | Q8: =SUM(B7:Q7)/Assumptions!$F$26 | R8: =SUM(B7:R7)/Assumptions!$F$26 | S8: =SUM(B7:S7)/Assumptions!$F$26 | T8: =SUM(B7:T7)/Assumptions!$F$26 | U8: =SUM(B7:U7)/Assumptions!$F$26 | V8: =SUM(B7:V7)/Assumptions!$F$26 | W8: =SUM(B7:W7)/Assumptions!$F$26 | X8: =SUM(B7:X7)/Assumptions!$F$26 | Y8: =SUM(B7:Y7)/Assumptions!$F$26
A9: Ending Net PP&E | B9: =B6+B7-B8 | C9: =C6+C7-C8 | D9: =D6+D7-D8 | E9: =E6+E7-E8 | F9: =F6+F7-F8 | G9: =G6+G7-G8 | H9: =H6+H7-H8 | I9: =I6+I7-I8 | ... Y9: =Y6+Y7-Y8

Sheet Checks
A1: Checks & QA
A2: Quality checks to prove the file is clean before client handoff.
B4: Core Checks
B5: Check | C5: Formula / Value | D5: Status | E5: Threshold
B6: Scenario selected | C6: =Control!C6
B7: First month BS balance | C7: =ABS(BS!B19) | D7: =IF(C7<1,"PASS","FAIL") | E7: < 1
B8: Last month BS balance | C8: =ABS(BS!Y19) | D8: =IF(C8<1,"PASS","FAIL") | E8: < 1
B9: Minimum ending cash | C9: =MIN(CF!B21:Y21) | D9: =IF(C9>0,"PASS","FAIL") | E9: > 0
B10: 2026 EBITDA margin | C10: =Dashboard!C16 | D10: =IF(C10>=0,"OK","REVIEW") | E10: review
B11: 2027 EBITDA margin | C11: =Dashboard!D16 | D11: =IF(C11>=0,"OK","REVIEW") | E11: review

Sheet Debt
A1: Debt Schedule
A2: Illustrative debt roll-forward with editable draws and repayments.
A3: Monthly Debt
B4: =Assumptions!$F$6 | C4: =DATE(YEAR(B4),MONTH(B4)+1,1) | D4: =DATE(YEAR(C4),MONTH(C4)+1,1) | E4: =DATE(YEAR(D4),MONTH(D4)+1,1) | F4: =DATE(YEAR(E4),MONTH(E4)+1,1) | G4: =DATE(YEAR(F4),MONTH(F4)+1,1) | H4: =DATE(YEAR(G4),MONTH(G4)+1,1) | I4: =DATE(YEAR(H4),MONTH(H4)+1,1) | J4: =DATE(YEAR(I4),MONTH(I4)+1,1) | ... Y4: =DATE(YEAR(X4),MONTH(X4)+1,1)
A6: Opening Debt | B6: =Assumptions!$F$11 | C6: =B9 | D6: =C9 | E6: =D9 | F6: =E9 | G6: =F9 | H6: =G9 | I6: =H9 | J6: =I9 | ... Y6: =X9
A7: Debt Draws | B7: =Data_Entry!B66 | C7: =Data_Entry!C66 | D7: =Data_Entry!D66 | E7: =Data_Entry!E66 | F7: =Data_Entry!F66 | G7: =Data_Entry!G66 | H7: =Data_Entry!H66 | I7: =Data_Entry!I66 | ... Y7: =Data_Entry!Y66
A8: Debt Repayments | B8: =Data_Entry!B67 | C8: =Data_Entry!C67 | D8: =Data_Entry!D67 | E8: =Data_Entry!E67 | F8: =Data_Entry!F67 | G8: =Data_Entry!G67 | H8: =Data_Entry!H67 | I8: =Data_Entry!I67 | ... Y8: =Data_Entry!Y67
A9: Ending Debt | B9: =B6+B7-B8 | C9: =C6+C7-C8 | D9: =D6+D7-D8 | E9: =E6+E7-E8 | F9: =F6+F7-F8 | G9: =G6+G7-G8 | H9: =H6+H7-H8 | I9: =I6+I7-I8 | ... Y9: =Y6+Y7-Y8
A10: Interest Expense | B10: =((B6+B9)/2)*Assumptions!$F$25/12 | C10: =((C6+C9)/2)*Assumptions!$F$25/12 | D10: =((D6+D9)/2)*Assumptions!$F$25/12 | E10: =((E6+E9)/2)*Assumptions!$F$25/12 | F10: =((F6+F9)/2)*Assumptions!$F$25/12 | G10: =((G6+G9)/2)*Assumptions!$F$25/12 | H10: =((H6+H9)/2)*Assumptions!$F$25/12 | I10: =((I6+I9)/2)*Assumptions!$F$25/12 | ... Y10: =((Y6+Y9)/2)*Assumptions!$F$25/12

Sheet IS
A1: Income Statement
A2: Integrated monthly P&L
A3: Monthly Income Statement
B4: =Assumptions!$F$6 | C4: =DATE(YEAR(B4),MONTH(B4)+1,1) | D4: =DATE(YEAR(C4),MONTH(C4)+1,1) | E4: =DATE(YEAR(D4),MONTH(D4)+1,1) | F4: =DATE(YEAR(E4),MONTH(E4)+1,1) | G4: =DATE(YEAR(F4),MONTH(F4)+1,1) | H4: =DATE(YEAR(G4),MONTH(G4)+1,1) | I4: =DATE(YEAR(H4),MONTH(H4)+1,1) | J4: =DATE(YEAR(I4),MONTH(I4)+1,1) | ... Y4: =DATE(YEAR(X4),MONTH(X4)+1,1)
A6: Total Revenue | B6: =Revenue!B15 | C6: =Revenue!C15 | D6: =Revenue!D15 | E6: =Revenue!E15 | F6: =Revenue!F15 | G6: =Revenue!G15 | H6: =Revenue!H15 | I6: =Revenue!I15 | ... Y6: =Revenue!Y15
A7: COGS | B7: =Revenue!B18 | C7: =Revenue!C18 | D7: =Revenue!D18 | E7: =Revenue!E18 | F7: =Revenue!F18 | G7: =Revenue!G18 | H7: =Revenue!H18 | I7: =Revenue!I18 | ... Y7: =Revenue!Y18
A8: Gross Profit | B8: =B6-B7 | C8: =C6-C7 | D8: =D6-D7 | E8: =E6-E7 | F8: =F6-F7 | G8: =G6-G7 | H8: =H6-H7 | I8: =I6-I7 | ... Y8: =Y6-Y7
A10: Payroll Expense | B10: =Opex!B6 | C10: =Opex!C6 | D10: =Opex!D6 | E10: =Opex!E6 | F10: =Opex!F6 | G10: =Opex!G6 | H10: =Opex!H6 | I10: =Opex!I6 | ... Y10: =Opex!Y6
A11: Non-Payroll Opex | B11: =Opex!B12-Opex!B6 | C11: =Opex!C12-Opex!C6 | D11: =Opex!D12-Opex!D6 | E11: =Opex!E12-Opex!E6 | F11: =Opex!F12-Opex!F6 | G11: =Opex!G12-Opex!G6 | H11: =Opex!H12-Opex!H6 | I11: =Opex!I12-Opex!I6 | ... Y11: =Opex!Y12-Opex!Y6
A12: EBITDA | B12: =B8-B10-B11 | C12: =C8-C10-C11 | D12: =D8-D10-D11 | E12: =E8-E10-E11 | F12: =F8-F10-F11 | G12: =G8-G10-G11 | H12: =H8-H10-H11 | I12: =I8-I10-I11 | ... Y12: =Y8-Y10-Y11
A13: Depreciation | B13: =Capex!B8 | C13: =Capex!C8 | D13: =Capex!D8 | E13: =Capex!E8 | F13: =Capex!F8 | G13: =Capex!G8 | H13: =Capex!H8 | I13: =Capex!I8 | ... Y13: =Capex!Y8
A14: EBIT | B14: =B12-B13 | C14: =C12-C13 | D14: =D12-D13 | E14: =E12-E13 | F14: =F12-F13 | G14: =G12-G13 | H14: =H12-H13 | I14: =I12-I13 | ... Y14: =Y12-Y13
A15: Interest | B15: =Debt!B10 | C15: =Debt!C10 | D15: =Debt!D10 | E15: =Debt!E10 | F15: =Debt!F10 | G15: =Debt!G10 | H15: =Debt!H10 | I15: =Debt!I10 | ... Y15: =Debt!Y10
A16: EBT | B16: =B14-B15 | C16: =C14-C15 | D16: =D14-D15 | E16: =E14-E15 | F16: =F14-F15 | G16: =G14-G15 | H16: =H14-H15 | I16: =I14-I15 | ... Y16: =Y14-Y15
A17: Taxes | B17: =MAX(0,B16*Assumptions!$F$22) | C17: =MAX(0,C16*Assumptions!$F$22) | D17: =MAX(0,D16*Assumptions!$F$22) | E17: =MAX(0,E16*Assumptions!$F$22) | F17: =MAX(0,F16*Assumptions!$F$22) | G17: =MAX(0,G16*Assumptions!$F$22) | H17: =MAX(0,H16*Assumptions!$F$22) | I17: =MAX(0,I16*Assumptions!$F$22) | ... Y17: =MAX(0,Y16*Assumptions!$F$22)
A18: Net Income | B18: =B16-B17 | C18: =C16-C17 | D18: =D16-D17 | E18: =E16-E17 | F18: =F16-F17 | G18: =G16-G17 | H18: =H16-H17 | I18: =I16-I17 | ... Y18: =Y16-Y17

Sheet Budget_vs_Actual
A1: Budget vs Actual – Monthly Variance Analysis
A2: HubSpot (HUBS) | FY2024 Forecast (Budget) vs Illustrative Actuals | USD
A3: Budget = Base Scenario from IS sheet. Actuals = illustrative ±variance for demo purposes.
A4: Legend: | C4: Budget | D4: Actual | E4: Variance $ | F4: Variance % | G4: Favourable | H4: Unfavourable
A6: Metric | B6: Jan-24 | F6: Feb-24 | J6: Mar-24 | N6: Apr-24 | R6: May-24 | V6: Jun-24 | Z6: Jul-24 | AD6: Aug-24 | AH6: Sep-24 | AL6: Oct-24 | AP6: Nov-24 | AT6: Dec-24 | AY6: FY2024 Budget | AZ6: FY2024 Actual | BA6: Total Var $ | BB6: Total Var %
B7: Budget | C7: Actual | D7: Var $ | E7: Var % | F7: Budget | G7: Actual | H7: Var $ | I7: Var % | J7: Budget | K7: Actual | L7: Var $ | M7: Var % | N7: Budget | O7: Actual | P7: Var $ | Q7: Var % | R7: Budget | S7: Actual | T7: Var $ | U7: Var % | V7: Budget | W7: Actual | X7: Var $ | Y7: Var % | Z7: Budget | AA7: Actual | AB7: Var $ | AC7: Var % | AD7: Budget | AE7: Actual | AF7: Var $ | AG7: Var % | AH7: Budget | AI7: Actual | AJ7: Var $ | AK7: Var % | AL7: Budget | AM7: Actual | AN7: Var $ | AO7: Var % | AP7: Budget | AQ7: Actual | AR7: Var $ | AS7: Var % | AT7: Budget | AU7: Actual | AV7: Var $ | AW7: Var %
A8: REVENUE
