Workbook

Sheet README
B2: TechFlow SaaS — Management Reporting & Variance Analysis
B3: Built by Minh Hoang | FP&A Specialist | Upwork Portfolio Project #3
B5: ABOUT THIS MODEL
B7: Company | C7: TechFlow Inc. — illustrative B2B SaaS company ($30M ARR range)
B8: Purpose | C8: Monthly management reporting package: Budget vs Actual P&L, variance analysis, revenue bridge, departmental cost breakdown, and KPI traffic light dashboard.
B9: Period | C9: FY2025 (Jan–Dec), monthly granularity with full-year rollup
B10: Currency | C10: USD
B11: Use Case | C11: Demonstrate real-world FP&A reporting workflow: data intake → variance analysis → executive commentary → decision support
B14: HOW TO USE
B16: Step 1 → Actuals sheet: Enter monthly actual figures in the YELLOW cells. Budget is pre-loaded.
B17: Step 2 → Variance_Analysis: Auto-calculates $ and % variance with color-coded flags (green = favourable, red = unfavourable).
B18: Step 3 → Revenue_Bridge: See the revenue variance decomposed into Price, Volume, and Mix effects.
B19: Step 4 → Cost_Breakdown: Departmental opex split with budget vs actual by department.
B20: Step 5 → KPI_Dashboard: Traffic light indicators for all key metrics — present to leadership.
B21: Step 6 → Commentary: Pre-filled executive commentary template with variance explanations.
B24: COLOUR GUIDE
B26: Blue text | C26: Input / editable assumption
B27: Black text | C27: Formula / calculation
B28: Green text | C28: Cross-sheet link
B29: Yellow background | C29: Cell requires attention / data entry
B30: Green background | C30: Favourable variance
B31: Red background | C31: Unfavourable variance

Sheet Actuals
B1: TechFlow SaaS — Monthly Actuals Data Entry
B2: Enter actual figures in YELLOW cells. Budget values are pre-loaded from the annual plan.
B4: Line Item | C4: Jan-25 | D4: Feb-25 | E4: Mar-25 | F4: Apr-25 | G4: May-25 | H4: Jun-25 | I4: Jul-25 | J4: Aug-25 | K4: Sep-25 | L4: Oct-25 | M4: Nov-25 | N4: Dec-25 | O4: FY2025
B5: ── BUDGET ──
B6: REVENUE
B7: Subscription Revenue | C7: 2450 | D7: 2475 | E7: 2500 | F7: 2530 | G7: 2560 | H7: 2590 | I7: 2625 | J7: 2660 | K7: 2695 | L7: 2730 | M7: 2770 | N7: 2810 | O7: =SUM(C7:N7) -> 31395
B8: Professional Services | C8: 180 | D8: 185 | E8: 190 | F8: 195 | G8: 200 | H8: 205 | I8: 210 | J8: 215 | K8: 220 | L8: 225 | M8: 230 | N8: 240 | O8: =SUM(C8:N8) -> 2495
B9: Total Revenue | C9: =C7+C8 -> 2630 | D9: =D7+D8 -> 2660 | E9: =E7+E8 -> 2690 | F9: =F7+F8 -> 2725 | G9: =G7+G8 -> 2760 | H9: =H7+H8 -> 2795 | I9: =I7+I8 -> 2835 | J9: =J7+J8 -> 2875 | ... N9: =N7+N8 -> 3050 | O9: =SUM(C9:N9) -> 33890
B11: COST OF GOODS SOLD
B12: Hosting & Infrastructure | C12: 245 | D12: 248 | E12: 250 | F12: 253 | G12: 256 | H12: 259 | I12: 263 | J12: 266 | K12: 270 | L12: 273 | M12: 277 | N12: 281 | O12: =SUM(C12:N12) -> 3141
B13: Customer Support | C13: 195 | D13: 197 | E13: 200 | F13: 202 | G13: 204 | H13: 207 | I13: 210 | J13: 212 | K13: 215 | L13: 218 | M13: 221 | N13: 224 | O13: =SUM(C13:N13) -> 2505
B14: Total COGS | C14: =C12+C13 -> 440 | D14: =D12+D13 -> 445 | E14: =E12+E13 -> 450 | F14: =F12+F13 -> 455 | G14: =G12+G13 -> 460 | H14: =H12+H13 -> 466 | I14: =I12+I13 -> 473 | J14: =J12+J13 -> 478 | ... N14: =N12+N13 -> 505 | O14: =SUM(C14:N14) -> 5646
B16: GROSS PROFIT | C16: =C9-C14 -> 2190 | D16: =D9-D14 -> 2215 | E16: =E9-E14 -> 2240 | F16: =F9-F14 -> 2270 | G16: =G9-G14 -> 2300 | H16: =H9-H14 -> 2329 | I16: =I9-I14 -> 2362 | J16: =J9-J14 -> 2397 | ... N16: =N9-N14 -> 2545 | O16: =SUM(C16:N16) -> 28244
B17: Gross Margin % | C17: =IF(C9=0,0,C16/C9) -> 0.83269962 | D17: =IF(D9=0,0,D16/D9) -> 0.83270677 | E17: =IF(E9=0,0,E16/E9) -> 0.83271375 | F17: =IF(F9=0,0,F16/F9) -> 0.83302752 | G17: =IF(G9=0,0,G16/G9) -> 0.83333333 | H17: =IF(H9=0,0,H16/H9) -> 0.8332737 | I17: =IF(I9=0,0,I16/I9) -> 0.83315697 | J17: =IF(J9=0,0,J16/J9) -> 0.83373913 | ... O17: =IF(O9=0,0,O16/O9) -> 0.83340218
B19: OPERATING EXPENSES
B20: Sales & Marketing | C20: 520 | D20: 530 | E20: 540 | F20: 550 | G20: 560 | H20: 570 | I20: 580 | J20: 590 | K20: 600 | L20: 610 | M20: 620 | N20: 640 | O20: =SUM(C20:N20) -> 6910
B21: Research & Development | C21: 680 | D21: 685 | E21: 690 | F21: 695 | G21: 700 | H21: 705 | I21: 710 | J21: 715 | K21: 720 | L21: 725 | M21: 730 | N21: 740 | O21: =SUM(C21:N21) -> 8495
B22: General & Administrative | C22: 280 | D22: 282 | E22: 284 | F22: 286 | G22: 288 | H22: 290 | I22: 292 | J22: 294 | K22: 296 | L22: 298 | M22: 300 | N22: 305 | O22: =SUM(C22:N22) -> 3495
B23: Total Opex | C23: =C20+C21+C22 -> 1480 | D23: =D20+D21+D22 -> 1497 | E23: =E20+E21+E22 -> 1514 | F23: =F20+F21+F22 -> 1531 | G23: =G20+G21+G22 -> 1548 | H23: =H20+H21+H22 -> 1565 | I23: =I20+I21+I22 -> 1582 | J23: =J20+J21+J22 -> 1599 | ... N23: =N20+N21+N22 -> 1685 | O23: =SUM(C23:N23) -> 18900
B25: EBITDA | C25: =C16-C23 -> 710 | D25: =D16-D23 -> 718 | E25: =E16-E23 -> 726 | F25: =F16-F23 -> 739 | G25: =G16-G23 -> 752 | H25: =H16-H23 -> 764 | I25: =I16-I23 -> 780 | J25: =J16-J23 -> 798 | ... N25: =N16-N23 -> 860 | O25: =SUM(C25:N25) -> 9344
B26: EBITDA Margin % | C26: =IF(C9=0,0,C25/C9) -> 0.26996198 | D26: =IF(D9=0,0,D25/D9) -> 0.26992481 | E26: =IF(E9=0,0,E25/E9) -> 0.26988848 | F26: =IF(F9=0,0,F25/F9) -> 0.27119266 | G26: =IF(G9=0,0,G25/G9) -> 0.27246377 | H26: =IF(H9=0,0,H25/H9) -> 0.27334526 | I26: =IF(I9=0,0,I25/I9) -> 0.27513228 | J26: =IF(J9=0,0,J25/J9) -> 0.27756522 | ... O26: =IF(O9=0,0,O25/O9) -> 0.27571555
B28: Depreciation & Amortization | C28: 85 | D28: 85 | E28: 85 | F28: 85 | G28: 85 | H28: 85 | I28: 90 | J28: 90 | K28: 90 | L28: 90 | M28: 90 | N28: 90 | O28: =SUM(C28:N28) -> 1050
B29: Interest Expense | C29: 12 | D29: 12 | E29: 12 | F29: 12 | G29: 12 | H29: 12 | I29: 12 | J29: 12 | K29: 12 | L29: 12 | M29: 12 | N29: 12 | O29: =SUM(C29:N29) -> 144
B30: EBT | C30: =C25-C28-C29 -> 613 | D30: =D25-D28-D29 -> 621 | E30: =E25-E28-E29 -> 629 | F30: =F25-F28-F29 -> 642 | G30: =G25-G28-G29 -> 655 | H30: =H25-H28-H29 -> 667 | I30: =I25-I28-I29 -> 678 | J30: =J25-J28-J29 -> 696 | ... N30: =N25-N28-N29 -> 758 | O30: =SUM(C30:N30) -> 8150
B31: Income Tax (21%) | C31: =MAX(0,C30*0.21) -> 128.73 | D31: =MAX(0,D30*0.21) -> 130.41 | E31: =MAX(0,E30*0.21) -> 132.09 | F31: =MAX(0,F30*0.21) -> 134.82 | G31: =MAX(0,G30*0.21) -> 137.55 | H31: =MAX(0,H30*0.21) -> 140.07 | I31: =MAX(0,I30*0.21) -> 142.38 | J31: =MAX(0,J30*0.21) -> 146.16 | ... N31: =MAX(0,N30*0.21) -> 159.18 | O31: =SUM(C31:N31) -> 1711.5
B32: NET INCOME | C32: =C30-C31 -> 484.27 | D32: =D30-D31 -> 490.59 | E32: =E30-E31 -> 496.91 | F32: =F30-F31 -> 507.18 | G32: =G30-G31 -> 517.45 | H32: =H30-H31 -> 526.93 | I32: =I30-I31 -> 535.62 | J32: =J30-J31 -> 549.84 | ... N32: =N30-N31 -> 598.82 | O32: =SUM(C32:N32) -> 6438.5
B34: ── ACTUALS ──
B35: Line Item | C35: Jan-25 | D35: Feb-25 | E35: Mar-25 | F35: Apr-25 | G35: May-25 | H35: Jun-25 | I35: Jul-25 | J35: Aug-25 | K35: Sep-25 | L35: Oct-25 | M35: Nov-25 | N35: Dec-25 | O35: FY2025
B36: REVENUE
B37: Subscription Revenue | C37: 2480 | D37: 2460 | E37: 2545 | F37: 2550 | G37: 2550 | H37: 2645 | I37: 2660 | J37: 2640 | K37: 2755 | L37: 2770 | M37: 2795 | N37: 2880 | O37: =SUM(C37:N37) -> 31730
B38: Professional Services | C38: 190 | D38: 180 | E38: 205 | F38: 187 | G38: 212 | H38: 213 | I38: 207 | J38: 233 | K38: 215 | L38: 239 | M38: 250 | N38: 250 | O38: =SUM(C38:N38) -> 2581
B39: Total Revenue | C39: =C37+C38 -> 2670 | D39: =D37+D38 -> 2640 | E39: =E37+E38 -> 2750 | F39: =F37+F38 -> 2737 | G39: =G37+G38 -> 2762 | H39: =H37+H38 -> 2858 | I39: =I37+I38 -> 2867 | J39: =J37+J38 -> 2873 | ... N39: =N37+N38 -> 3130 | O39: =SUM(C39:N39) -> 34311
B41: COST OF GOODS SOLD
B42: Hosting & Infrastructure | C42: 250 | D42: 245 | E42: 258 | F42: 255 | G42: 252 | H42: 269 | I42: 269 | J42: 264 | K42: 282 | L42: 277 | M42: 285 | N42: 296 | O42: =SUM(C42:N42) -> 3202
B43: Customer Support | C43: 190 | D43: 200 | E43: 202 | F43: 198 | G43: 210 | H43: 204 | I43: 218 | J43: 214 | K43: 209 | L43: 223 | M43: 224 | N43: 231 | O43: =SUM(C43:N43) -> 2523
B44: Total COGS | C44: =C42+C43 -> 440 | D44: =D42+D43 -> 445 | E44: =E42+E43 -> 460 | F44: =F42+F43 -> 453 | G44: =G42+G43 -> 462 | H44: =H42+H43 -> 473 | I44: =I42+I43 -> 487 | J44: =J42+J43 -> 478 | ... N44: =N42+N43 -> 527 | O44: =SUM(C44:N44) -> 5725
B46: GROSS PROFIT | C46: =C39-C44 -> 2230 | D46: =D39-D44 -> 2195 | E46: =E39-E44 -> 2290 | F46: =F39-F44 -> 2284 | G46: =G39-G44 -> 2300 | H46: =H39-H44 -> 2385 | I46: =I39-I44 -> 2380 | J46: =J39-J44 -> 2395 | ... N46: =N39-N44 -> 2603 | O46: =SUM(C46:N46) -> 28586
B47: Gross Margin % | C47: =IF(C39=0,0,C46/C39) -> 0.83520599 | D47: =IF(D39=0,0,D46/D39) -> 0.83143939 | E47: =IF(E39=0,0,E46/E39) -> 0.83272727 | F47: =IF(F39=0,0,F46/F39) -> 0.83449032 | G47: =IF(G39=0,0,G46/G39) -> 0.83272991 | H47: =IF(H39=0,0,H46/H39) -> 0.83449965 | I47: =IF(I39=0,0,I46/I39) -> 0.83013603 | J47: =IF(J39=0,0,J46/J39) -> 0.83362339 | ... O47: =IF(O39=0,0,O46/O39) -> 0.83314389
B49: OPERATING EXPENSES
B50: Sales & Marketing | C50: 535 | D50: 520 | E50: 560 | F50: 558 | G50: 545 | H50: 595 | I50: 592 | J50: 582 | K50: 618 | L50: 620 | M50: 615 | N50: 670 | O50: =SUM(C50:N50) -> 7010
...

Sheet Variance_Analysis
B1: TechFlow SaaS — Budget vs Actual Variance Analysis | FY2025
B2: Green = Favourable | Red = Unfavourable | All amounts in $000s. Formulas link to Actuals sheet.
B4: Line Item | C4: Budget (FY) | D4: Actual (FY) | E4: Variance $ | F4: Variance % | H4: Status | I4: Q1 Bud | J4: Q1 Act | K4: Q1 Var $
B5: Subscription Revenue | C5: =Actuals!O7 -> 31395 | D5: =Actuals!O37 -> 31730 | E5: =D5-C5 -> 335 | F5: =IF(C5=0,0,E5/ABS(C5)) -> 0.010670489 | H5: =IF(E5>0,"✓ Favourable",IF(E5<0,"✗ Unfavourable","On Budget")) -> ✓ Favourable | I5: =SUM(Actuals!C7:E7) -> 7425 | J5: =SUM(Actuals!C37:E37) -> 7485 | K5: =J5-I5 -> 60
B6: Professional Services | C6: =Actuals!O8 -> 2495 | D6: =Actuals!O38 -> 2581 | E6: =D6-C6 -> 86 | F6: =IF(C6=0,0,E6/ABS(C6)) -> 0.034468938 | H6: =IF(E6>0,"✓ Favourable",IF(E6<0,"✗ Unfavourable","On Budget")) -> ✓ Favourable | I6: =SUM(Actuals!C8:E8) -> 555 | J6: =SUM(Actuals!C38:E38) -> 575 | K6: =J6-I6 -> 20
B7: Total Revenue | C7: =Actuals!O9 -> 33890 | D7: =Actuals!O39 -> 34311 | E7: =D7-C7 -> 421 | F7: =IF(C7=0,0,E7/ABS(C7)) -> 0.012422544 | H7: =IF(E7>0,"✓ Favourable",IF(E7<0,"✗ Unfavourable","On Budget")) -> ✓ Favourable | I7: =SUM(Actuals!C9:E9) -> 7980 | J7: =SUM(Actuals!C39:E39) -> 8060 | K7: =J7-I7 -> 80
B9: Total COGS | C9: =Actuals!O14 -> 5646 | D9: =Actuals!O44 -> 5725 | E9: =C9-D9 -> -79 | F9: =IF(C9=0,0,E9/ABS(C9)) -> -0.013992207 | H9: =IF(E9>0,"✓ Favourable",IF(E9<0,"✗ Unfavourable","On Budget")) -> ✗ Unfavourable | I9: =SUM(Actuals!C14:E14) -> 1335 | J9: =SUM(Actuals!C44:E44) -> 1345 | K9: =I9-J9 -> -10
B10: GROSS PROFIT | C10: =Actuals!O16 -> 28244 | D10: =Actuals!O46 -> 28586 | E10: =D10-C10 -> 342 | F10: =IF(C10=0,0,E10/ABS(C10)) -> 0.012108766 | H10: =IF(E10>0,"✓ Favourable",IF(E10<0,"✗ Unfavourable","On Budget")) -> ✓ Favourable | I10: =SUM(Actuals!C16:E16) -> 6645 | J10: =SUM(Actuals!C46:E46) -> 6715 | K10: =J10-I10 -> 70
B12: Sales & Marketing | C12: =Actuals!O20 -> 6910 | D12: =Actuals!O50 -> 7010 | E12: =C12-D12 -> -100 | F12: =IF(C12=0,0,E12/ABS(C12)) -> -0.01447178 | H12: =IF(E12>0,"✓ Favourable",IF(E12<0,"✗ Unfavourable","On Budget")) -> ✗ Unfavourable | I12: =SUM(Actuals!C20:E20) -> 1590 | J12: =SUM(Actuals!C50:E50) -> 1615 | K12: =I12-J12 -> -25
B13: Research & Development | C13: =Actuals!O21 -> 8495 | D13: =Actuals!O51 -> 8520 | E13: =C13-D13 -> -25 | F13: =IF(C13=0,0,E13/ABS(C13)) -> -0.0029429076 | H13: =IF(E13>0,"✓ Favourable",IF(E13<0,"✗ Unfavourable","On Budget")) -> ✗ Unfavourable | I13: =SUM(Actuals!C21:E21) -> 2055 | J13: =SUM(Actuals!C51:E51) -> 2045 | K13: =I13-J13 -> 10
B14: General & Administrative | C14: =Actuals!O22 -> 3495 | D14: =Actuals!O52 -> 3520 | E14: =C14-D14 -> -25 | F14: =IF(C14=0,0,E14/ABS(C14)) -> -0.0071530758 | H14: =IF(E14>0,"✓ Favourable",IF(E14<0,"✗ Unfavourable","On Budget")) -> ✗ Unfavourable | I14: =SUM(Actuals!C22:E22) -> 846 | J14: =SUM(Actuals!C52:E52) -> 852 | K14: =I14-J14 -> -6
B15: Total Opex | C15: =Actuals!O23 -> 18900 | D15: =Actuals!O53 -> 19050 | E15: =C15-D15 -> -150 | F15: =IF(C15=0,0,E15/ABS(C15)) -> -0.0079365079 | H15: =IF(E15>0,"✓ Favourable",IF(E15<0,"✗ Unfavourable","On Budget")) -> ✗ Unfavourable | I15: =SUM(Actuals!C23:E23) -> 4491 | J15: =SUM(Actuals!C53:E53) -> 4512 | K15: =I15-J15 -> -21
B17: EBITDA | C17: =Actuals!O25 -> 9344 | D17: =Actuals!O55 -> 9536 | E17: =D17-C17 -> 192 | F17: =IF(C17=0,0,E17/ABS(C17)) -> 0.020547945 | H17: =IF(E17>0,"✓ Favourable",IF(E17<0,"✗ Unfavourable","On Budget")) -> ✓ Favourable | I17: =SUM(Actuals!C25:E25) -> 2154 | J17: =SUM(Actuals!C55:E55) -> 2203 | K17: =J17-I17 -> 49
B18: NET INCOME | C18: =Actuals!O32 -> 6438.5 | D18: =Actuals!O62 -> 6582.28 | E18: =D18-C18 -> 143.78 | F18: =IF(C18=0,0,E18/ABS(C18)) -> 0.022331288 | H18: =IF(E18>0,"✓ Favourable",IF(E18<0,"✗ Unfavourable","On Budget")) -> ✓ Favourable | I18: =SUM(Actuals!C32:E32) -> 1471.77 | J18: =SUM(Actuals!C62:E62) -> 1510.48 | K18: =J18-I18 -> 38.71

Sheet KPI_Dashboard
B1: TechFlow SaaS — KPI Traffic Light Dashboard | FY2025
B2: Auto-linked to Actuals sheet. Present this page to leadership.
B4: KPI | C4: Budget | D4: Actual | E4: Variance | F4: Status | G4: Commentary
B5: Total Revenue ($K) | C5: =Actuals!O9 -> 33890 | D5: =Actuals!O39 -> 34311 | E5: =D5-C5 -> 421 | F5: =IF(E5>0,"🟢 On Track",IF(E5<-100,"🔴 Below Plan","🟡 Monitor")) -> 🟢 On Track | G5: Revenue beat driven by strong subscription growth
B6: Gross Margin % | C6: =IF(Actuals!O9=0,0,Actuals!O16/Actuals!O9) -> 0.83340218 | D6: =IF(Actuals!O39=0,0,Actuals!O46/Actuals!O39) -> 0.83314389 | E6: =D6-C6 -> -0.00025829382 | F6: =IF(E6>=0,"🟢 On Track",IF(E6<-0.02,"🔴 Below Plan","🟡 Monitor")) -> 🟡 Monitor | G6: Margin stable despite infrastructure cost pressure
B7: EBITDA ($K) | C7: =Actuals!O25 -> 9344 | D7: =Actuals!O55 -> 9536 | E7: =D7-C7 -> 192 | F7: =IF(E7>0,"🟢 On Track",IF(E7<-100,"🔴 Below Plan","🟡 Monitor")) -> 🟢 On Track | G7: Opex discipline offset by higher S&M spend
B8: Net Income ($K) | C8: =Actuals!O32 -> 6438.5 | D8: =Actuals!O62 -> 6582.28 | E8: =D8-C8 -> 143.78 | F8: =IF(E8>0,"🟢 On Track",IF(E8<-100,"🔴 Below Plan","🟡 Monitor")) -> 🟢 On Track | G8: Tax benefit from lower effective rate
B9: S&M as % Revenue | C9: =IF(Actuals!O9=0,0,Actuals!O20/Actuals!O9) -> 0.20389495 | D9: =IF(Actuals!O39=0,0,Actuals!O50/Actuals!O39) -> 0.20430766 | E9: =D9-C9 -> 0.00041270217 | F9: =IF(ABS(E9)<0.005,"🟢 On Track",IF(E9>0.01,"🔴 Over Budget","🟡 Monitor")) -> 🟢 On Track | G9: Slightly above plan — monitor CAC efficiency
B10: R&D as % Revenue | C10: =IF(Actuals!O9=0,0,Actuals!O21/Actuals!O9) -> 0.25066391 | D10: =IF(Actuals!O39=0,0,Actuals!O51/Actuals!O39) -> 0.24831687 | E10: =D10-C10 -> -0.0023470463 | F10: =IF(ABS(E10)<0.005,"🟢 On Track","🟡 Monitor") -> 🟢 On Track | G10: On track with product roadmap investment

Sheet Commentary
B1: TechFlow SaaS — Executive Variance Commentary | FY2025
B2: Pre-filled template. Update commentary each month before leadership review.
B4: Category | C4: Commentary | D4: Action / Owner
B5: Revenue | C5: Subscription revenue tracking $335K above plan YTD, driven by higher-than-expected enterprise deal velocity in Q1 and Q3. Professional services revenue mixed — Q2 shortfall offset by Q3 recovery. | D5: RevOps to update pipeline forecast by 15th
B6: Gross Margin | C6: Gross margin stable at ~86% vs 83.3% budget. Hosting costs rising with user growth but offset by infrastructure optimization project completed in Q2. | D6: Infra team to present cost roadmap at next QBR
B7: Sales & Marketing | C7: S&M spend $100K over plan YTD. Incremental spend allocated to paid acquisition following strong Q1 pipeline conversion. CAC payback within 12-month target. | D7: CMO reviewing channel mix efficiency for Q4
B8: R&D | C8: R&D spend approximately on plan. Hiring 2 months behind schedule (tight market) created temporary underspend. Contractors engaged to maintain roadmap velocity. | D8: VP Eng to present updated hiring timeline
B9: G&A | C9: G&A tracking $25K over plan driven by legal costs for SOC 2 certification (one-time). Underlying run rate on track. | D9: CFO to reclassify SOC 2 costs to project bucket
B10: EBITDA | C10: EBITDA favourable to plan driven by revenue beat partially offset by S&M overspend. Margin compression expected in Q4 as deferred hires start. | D10: FP&A to update rolling forecast by month-end
B11: Cash & Liquidity | C11: No cash concerns. Operating cash flow positive every month. Runway >18 months at current burn. | D11: Treasury to present investment options for excess cash
